Workbook

Sheet National Summary
A1: SUMMARY | B1: 2020 Generation | C1: 2025 Generation | D1: 2030 Generation | E1: Assumptions
A2: Current measures (TWh) | B2: ='Data by plant and state'!O108 -> 791.76006 | C2: ='Data by plant and state'!P108 -> 782.28976 | D2: ='Data by plant and state'!Q108 -> 782.28976 | E2: Between 2020 and 2025, 26,670,299 MWh of generation are lost due to retired capacity in IA, MI, and NY, while all other at-risk capacity is saved by state and federal policy. In addition, Georgia Vogtle Units 3 & 4 come online. No changes to total capacity are assumed to occur between 2025 and 2030.
A3: Current measures (EJ) | B3: ='Data by plant and state'!W108 -> 2.8503362 | C3: ='Data by plant and state'!X108 -> 2.8162431 | D3: ='Data by plant and state'!Y108 -> 2.8162431
B7: 2020 (EJ) | C7: 2025 (EJ) | D7: 2030 (EJ)
A8: AL | B8: 0.14206618 | C8: 0.14206618 | D8: 0.14206618
A9: AR | B9: 0.045794945 | C9: 0.045794945 | D9: 0.045794945
A10: AZ | B10: 0.11195013 | C10: 0.11195013 | D10: 0.11195013
A11: CA | B11: 0.065568668 | C11: 0.065568668 | D11: 0.065568668
A12: CT | B12: 0.060773371 | C12: 0.060773371 | D12: 0.060773371
A13: FL | B13: 0.10552446 | C13: 0.10552446 | D13: 0.10552446
A14: GA | B14: 0.12370563 | C14: 0.18562563 | D14: 0.18562563
A15: IA | B15: 0.017623436 | C15: 0 | D15: 0
A16: IL | B16: 0.3531655 | C16: 0.3531655 | D16: 0.3531655
A17: KS | B17: 0.03300584 | C17: 0.03300584 | D17: 0.03300584
A18: LA | B18: 0.061749295 | C18: 0.061749295 | D18: 0.061749295
A19: MA | B19: 0 | C19: 0 | D19: 0
... A37: WI | B37: 0.036464839 | C37: 0.036464839 | D37: 0.036464839

Sheet Data by plant and state
A1: U.S. Department of Energy, The Energy Information Administration (EIA)
A2: Monthly Nuclear Utility Generation (MWh) by State and Reactor, 2018 December
A3: Sources: EIA-923 and EIA-860 Reports
E5: MWh | F5: Current Capacity (MWe) | H5: % of Summer Capacity | K5: Current Measures (MWh) | O5: Current Measures (TWh) | S5: Current Measures (EJ) | W5: GCAM input (EJ)
A6: State | B6: Plant ID | C6: Plant Name | D6: Unit ID | E6: 2018 Year_to_Date | F6: Nameplate | G6: Summer | H6: Utilization Factor | I6: Status | J6: Closing | K6: 2020 MWh | L6: 2025 MWh | M6: 2030 MWh | O6: 2020 (TWh) | P6: 2025 (TWh) | Q6: 2030 (TWh) | S6: 2020 (EJ) | T6: 2025 (EJ) | U6: 2030 (EJ) | W6: 2020 (EJ) | X6: 2025 (EJ) | Y6: 2030 (EJ)
A7: AL | B7: 46 | C7: Browns Ferry | D7: 1 | E7: 7841125 | F7: 1152 | G7: 1256 | H7: 71.3 | I7: Open | K7: 7841125 | L7: 7841125 | M7: 7841125 | N7: AL | O7: =K7/1000000 -> 7.841125 | P7: =L7/1000000 -> 7.841125 | Q7: =M7/1000000 -> 7.841125 | R7: AL | S7: =O7*0.0036 -> 0.02822805 | T7: =P7*0.0036 -> 0.02822805 | U7: =Q7*0.0036 -> 0.02822805 | V7: AL | W7: =SUM(S7:S11) -> 0.14206618 | X7: =SUM(T7:T11) -> 0.14206618 | Y7: =SUM(U7:U11) -> 0.14206618
A8: AL | B8: 46 | C8: Browns Ferry | D8: 2 | E8: 9457539 | F8: 1152 | G8: 1104 | H8: 97.8 | I8: Open | K8: 9457539 | L8: 9457539 | M8: 9457539 | N8: AL | O8: =K8/1000000 -> 9.457539 | P8: =L8/1000000 -> 9.457539 | Q8: =M8/1000000 -> 9.457539 | R8: AL | S8: =O8*0.0036 -> 0.03404714 | T8: =P8*0.0036 -> 0.03404714 | U8: =Q8*0.0036 -> 0.03404714
A9: AL | B9: 46 | C9: Browns Ferry | D9: 3 | E9: 8099117 | F9: 1190 | G9: 1260 | H9: 73.4 | I9: Open | K9: 8099117 | L9: 8099117 | M9: 8099117 | N9: AL | O9: =K9/1000000 -> 8.099117 | P9: =L9/1000000 -> 8.099117 | Q9: =M9/1000000 -> 8.099117 | R9: AL | S9: =O9*0.0036 -> 0.029156821 | T9: =P9*0.0036 -> 0.029156821 | U9: =Q9*0.0036 -> 0.029156821
A10: AL | B10: 6001 | C10: Joseph M Farley | D10: 1 | E10: 6409664 | F10: 888 | G10: 874 | H10: 83.7 | I10: Open | K10: 6409664 | L10: 6409664 | M10: 6409664 | N10: AL | O10: =K10/1000000 -> 6.409664 | P10: =L10/1000000 -> 6.409664 | Q10: =M10/1000000 -> 6.409664 | R10: AL | S10: =O10*0.0036 -> 0.02307479 | T10: =P10*0.0036 -> 0.02307479 | U10: =Q10*0.0036 -> 0.02307479
A11: AL | B11: 6001 | C11: Joseph M Farley | D11: 2 | E11: 7655382 | F11: 888 | G11: 877 | H11: 99.6 | I11: Open | K11: 7655382 | L11: 7655382 | M11: 7655382 | N11: AL | O11: =K11/1000000 -> 7.655382 | P11: =L11/1000000 -> 7.655382 | Q11: =M11/1000000 -> 7.655382 | R11: AL | S11: =O11*0.0036 -> 0.027559375 | T11: =P11*0.0036 -> 0.027559375 | U11: =Q11*0.0036 -> 0.027559375
A12: AR | B12: 8055 | C12: Arkansas Nuclear One | D12: 1 | E12: 5622437 | F12: 903 | G12: 833 | H12: 77 | I12: Open | K12: 5622437 | L12: 5622437 | M12: 5622437 | N12: AR | O12: =K12/1000000 -> 5.622437 | P12: =L12/1000000 -> 5.622437 | Q12: =M12/1000000 -> 5.622437 | R12: AR | S12: =O12*0.0036 -> 0.020240773 | T12: =P12*0.0036 -> 0.020240773 | U12: =Q12*0.0036 -> 0.020240773 | V12: AR | W12: =SUM(S12:S13) -> 0.045794945 | X12: =SUM(T12:T13) -> 0.045794945 | Y12: =SUM(U12:U13) -> 0.045794945
A13: AR | B13: 8055 | C13: Arkansas Nuclear One | D13: 2 | E13: 7098381 | F13: 943 | G13: 985 | H13: 82.3 | I13: Open | K13: 7098381 | L13: 7098381 | M13: 7098381 | N13: AR | O13: =K13/1000000 -> 7.098381 | P13: =L13/1000000 -> 7.098381 | Q13: =M13/1000000 -> 7.098381 | R13: AR | S13: =O13*0.0036 -> 0.025554172 | T13: =P13*0.0036 -> 0.025554172 | U13: =Q13*0.0036 -> 0.025554172
A14: AZ | B14: 6008 | C14: Palo Verde | D14: 1 | E14: 11220879 | F14: 1403 | G14: 1311 | H14: 97.7 | I14: Open | K14: 11220879 | L14: 11220879 | M14: 11220879 | N14: AZ | O14: =K14/1000000 -> 11.220879 | P14: =L14/1000000 -> 11.220879 | Q14: =M14/1000000 -> 11.220879 | R14: AZ | S14: =O14*0.0036 -> 0.040395164 | T14: =P14*0.0036 -> 0.040395164 | U14: =Q14*0.0036 -> 0.040395164 | V14: AZ | W14: =SUM(S14:S16) -> 0.11195013 | X14: =SUM(T14:T16) -> 0.11195013 | Y14: =SUM(U14:U16) -> 0.11195013
A15: AZ | B15: 6008 | C15: Palo Verde | D15: 2 | E15: 9448932 | F15: 1403 | G15: 1314 | H15: 82.1 | I15: Open | K15: 9448932 | L15: 9448932 | M15: 9448932 | N15: AZ | O15: =K15/1000000 -> 9.448932 | P15: =L15/1000000 -> 9.448932 | Q15: =M15/1000000 -> 9.448932 | R15: AZ | S15: =O15*0.0036 -> 0.034016155 | T15: =P15*0.0036 -> 0.034016155 | U15: =Q15*0.0036 -> 0.034016155
A16: AZ | B16: 6008 | C16: Palo Verde | D16: 3 | E16: 10427448 | F16: 1403 | G16: 1312 | H16: 90.7 | I16: Open | K16: 10427448 | L16: 10427448 | M16: 10427448 | N16: AZ | O16: =K16/1000000 -> 10.427448 | P16: =L16/1000000 -> 10.427448 | Q16: =M16/1000000 -> 10.427448 | R16: AZ | S16: =O16*0.0036 -> 0.037538813 | T16: =P16*0.0036 -> 0.037538813 | U16: =Q16*0.0036 -> 0.037538813
A17: CA | B17: 6099 | C17: Diablo Canyon | D17: 1 | E17: 9703806 | F17: 1159 | G17: 1122 | H17: 98.7 | I17: Saved by state policy | K17: 9703806 | L17: 9703806 | M17: 9703806 | N17: CA | O17: =K17/1000000 -> 9.703806 | P17: =L17/1000000 -> 9.703806 | Q17: =M17/1000000 -> 9.703806 | R17: CA | S17: =O17*0.0036 -> 0.034933702 | T17: =P17*0.0036 -> 0.034933702 | U17: =Q17*0.0036 -> 0.034933702 | V17: CA | W17: =SUM(S17:S18) -> 0.065568668 | X17: =SUM(T17:T18) -> 0.065568668 | Y17: =SUM(U17:U18) -> 0.065568668
A18: CA | B18: 6099 | C18: Diablo Canyon | D18: 2 | E18: 8509713 | F18: 1164 | G18: 1118 | H18: 86.9 | I18: Saved by state policy | K18: 8509713 | L18: 8509713 | M18: 8509713 | N18: CA | O18: =K18/1000000 -> 8.509713 | P18: =L18/1000000 -> 8.509713 | Q18: =M18/1000000 -> 8.509713 | R18: CA | S18: =O18*0.0036 -> 0.030634967 | T18: =P18*0.0036 -> 0.030634967 | U18: =Q18*0.0036 -> 0.030634967
A19: CT | B19: 566 | C19: Millstone | D19: 2 | E19: 6147489 | F19: 910 | G19: 868 | H19: 80.9 | I19: Saved by state policy | K19: 6147489 | L19: 6147489 | M19: 6147489 | N19: CT | O19: =K19/1000000 -> 6.147489 | P19: =L19/1000000 -> 6.147489 | Q19: =M19/1000000 -> 6.147489 | R19: CT | S19: =O19*0.0036 -> 0.02213096 | T19: =P19*0.0036 -> 0.02213096 | U19: =Q19*0.0036 -> 0.02213096 | V19: CT | W19: =SUM(S19:S20) -> 0.060773371 | X19: =SUM(T19:T20) -> 0.060773371 | Y19: =SUM(U19:U20) -> 0.060773371
A20: CT | B20: 566 | C20: Millstone | D20: 3 | E20: 10734003 | F20: 1253 | G20: 1220 | H20: 100.4 | I20: Saved by state policy | K20: 10734003 | L20: 10734003 | M20: 10734003 | N20: CT | O20: =K20/1000000 -> 10.734003 | P20: =L20/1000000 -> 10.734003 | Q20: =M20/1000000 -> 10.734003 | R20: CT | S20: =O20*0.0036 -> 0.038642411 | T20: =P20*0.0036 -> 0.038642411 | U20: =Q20*0.0036 -> 0.038642411
A21: FL | B21: 621 | C21: Turkey Point | D21: 3 | E21: 6457621 | F21: 877 | G21: 802 | H21: 91.9 | I21: Open | K21: 6457621 | L21: 6457621 | M21: 6457621 | N21: FL | O21: =K21/1000000 -> 6.457621 | P21: =L21/1000000 -> 6.457621 | Q21: =M21/1000000 -> 6.457621 | R21: FL | S21: =O21*0.0036 -> 0.023247436 | T21: =P21*0.0036 -> 0.023247436 | U21: =Q21*0.0036 -> 0.023247436 | V21: FL | W21: =SUM(S21:S24) -> 0.10552446 | X21: =SUM(T21:T24) -> 0.10552446 | Y21: =SUM(U21:U24) -> 0.10552446
A22: FL | B22: 621 | C22: Turkey Point | D22: 4 | E22: 7292147 | F22: 760 | G22: 802 | H22: 103.8 | I22: Open | K22: 7292147 | L22: 7292147 | M22: 7292147 | N22: FL | O22: =K22/1000000 -> 7.292147 | P22: =L22/1000000 -> 7.292147 | Q22: =M22/1000000 -> 7.292147 | R22: FL | S22: =O22*0.0036 -> 0.026251729 | T22: =P22*0.0036 -> 0.026251729 | U22: =Q22*0.0036 -> 0.026251729
A23: FL | B23: 6045 | C23: St Lucie | D23: 1 | E23: 7914552 | F23: 1080 | G23: 981 | H23: 92.1 | I23: Open | K23: 7914552 | L23: 7914552 | M23: 7914552 | N23: FL | O23: =K23/1000000 -> 7.914552 | P23: =L23/1000000 -> 7.914552 | Q23: =M23/1000000 -> 7.914552 | R23: FL | S23: =O23*0.0036 -> 0.028492387 | T23: =P23*0.0036 -> 0.028492387 | U23: =Q23*0.0036 -> 0.028492387
A24: FL | B24: 6045 | C24: St Lucie | D24: 2 | E24: 7648029 | F24: 1080 | G24: 987 | H24: 88.5 | I24: Open | K24: 7648029 | L24: 7648029 | M24: 7648029 | N24: FL | O24: =K24/1000000 -> 7.648029 | P24: =L24/1000000 -> 7.648029 | Q24: =M24/1000000 -> 7.648029 | R24: FL | S24: =O24*0.0036 -> 0.027532904 | T24: =P24*0.0036 -> 0.027532904 | U24: =Q24*0.0036 -> 0.027532904
A25: GA | C25: Georgia Vogtle | D25: 1 & 2 | I25: Opening | J25: 2023 | K25: 0 | L25: 17200000 | M25: 17200000 | N25: GA | O25: =K25/1000000 -> 0 | P25: =L25/1000000 -> 17.2 | Q25: =M25/1000000 -> 17.2 | R25: GA | S25: =O25*0.0036 -> 0 | T25: =P25*0.0036 -> 0.06192 | U25: =Q25*0.0036 -> 0.06192 | V25: GA | W25: =SUM(S25:S29) -> 0.12370563 | X25: =SUM(T25:T29) -> 0.18562563 | Y25: =SUM(U25:U29) -> 0.18562563
A26: GA | B26: 649 | C26: Vogtle | D26: 1 | E26: 9627221 | F26: 1160 | G26: 1150 | H26: 95.6 | I26: Open | K26: 9627221 | L26: 9627221 | M26: 9627221 | N26: GA | O26: =K26/1000000 -> 9.627221 | P26: =L26/1000000 -> 9.627221 | Q26: =M26/1000000 -> 9.627221 | R26: GA | S26: =O26*0.0036 -> 0.034657996 | T26: =P26*0.0036 -> 0.034657996 | U26: =Q26*0.0036 -> 0.034657996
A27: GA | B27: 649 | C27: Vogtle | D27: 2 | E27: 10331905 | F27: 1160 | G27: 1152 | H27: 102.4 | I27: Open | K27: 10331905 | L27: 10331905 | M27: 10331905 | N27: GA | O27: =K27/1000000 -> 10.331905 | P27: =L27/1000000 -> 10.331905 | Q27: =M27/1000000 -> 10.331905 | R27: GA | S27: =O27*0.0036 -> 0.037194858 | T27: =P27*0.0036 -> 0.037194858 | U27: =Q27*0.0036 -> 0.037194858
A28: GA | B28: 6051 | C28: Edwin I Hatch | D28: 1 | E28: 7009585 | F28: 857 | G28: 876 | H28: 91.3 | I28: Open | K28: 7009585 | L28: 7009585 | M28: 7009585 | N28: GA | O28: =K28/1000000 -> 7.009585 | P28: =L28/1000000 -> 7.009585 | Q28: =M28/1000000 -> 7.009585 | R28: GA | S28: =O28*0.0036 -> 0.025234506 | T28: =P28*0.0036 -> 0.025234506 | U28: =Q28*0.0036 -> 0.025234506
A29: GA | B29: 6051 | C29: Edwin I Hatch | D29: 2 | E29: 7393965 | F29: 865 | G29: 883 | H29: 95.6 | I29: Open | K29: 7393965 | L29: 7393965 | M29: 7393965 | N29: GA | O29: =K29/1000000 -> 7.393965 | P29: =L29/1000000 -> 7.393965 | Q29: =M29/1000000 -> 7.393965 | R29: GA | S29: =O29*0.0036 -> 0.026618274 | T29: =P29*0.0036 -> 0.026618274 | U29: =Q29*0.0036 -> 0.026618274
A30: IA | B30: 1060 | C30: Duane Arnold Energy Center | D30: 1 | E30: 4895399 | F30: 680 | G30: 601 | H30: 92.9 | I30: Already retired | J30: 2020 | K30: 4895399 | L30: 0 | M30: 0 | N30: IA | O30: =K30/1000000 -> 4.895399 | P30: =L30/1000000 -> 0 | Q30: =M30/1000000 -> 0 | R30: IA | S30: =O30*0.0036 -> 0.017623436 | T30: =P30*0.0036 -> 0 | U30: =Q30*0.0036 -> 0 | V30: IA | W30: =S30 -> 0.017623436 | X30: =T30 -> 0 | Y30: =U30 -> 0
A31: IL | B31: 204 | C31: Clinton Power Station | D31: 1 | E31: 8346686 | F31: 1138 | G31: 1060 | H31: 89.9 | I31: Saved by state policy | K31: 8346686 | L31: 8346686 | M31: 8346686 | N31: IL | O31: =K31/1000000 -> 8.346686 | P31: =L31/1000000 -> 8.346686 | Q31: =M31/1000000 -> 8.346686 | R31: IL | S31: =O31*0.0036 -> 0.03004807 | T31: =P31*0.0036 -> 0.03004807 | U31: =Q31*0.0036 -> 0.03004807 | V31: IL | W31: =SUM(S31:S41) -> 0.3531655 | X31: =SUM(T31:T41) -> 0.3531655 | Y31: =SUM(U31:U41) -> 0.3531655
A32: IL | B32: 880 | C32: Quad Cities Generating Station | D32: 1 | E32: 8051911 | F32: 1009 | G32: 908 | H32: 101.2 | I32: Saved by state policy | K32: 8051911 | L32: 8051911 | M32: 8051911 | N32: IL | O32: =K32/1000000 -> 8.051911 | P32: =L32/1000000 -> 8.051911 | Q32: =M32/1000000 -> 8.051911 | R32: IL | S32: =O32*0.0036 -> 0.02898688 | T32: =P32*0.0036 -> 0.02898688 | U32: =Q32*0.0036 -> 0.02898688
A33: IL | B33: 880 | C33: Quad Cities Generating Station | D33: 2 | E33: 7424547 | F33: 1009 | G33: 911 | H33: 93 | I33: Saved by state policy | K33: 7424547 | L33: 7424547 | M33: 7424547 | N33: IL | O33: =K33/1000000 -> 7.424547 | P33: =L33/1000000 -> 7.424547 | Q33: =M33/1000000 -> 7.424547 | R33: IL | S33: =O33*0.0036 -> 0.026728369 | T33: =P33*0.0036 -> 0.026728369 | U33: =Q33*0.0036 -> 0.026728369
A34: IL | B34: 869 | C34: Dresden Generating Station | D34: 2 | E34: 8052440 | F34: 1009 | G34: 902 | H34: 101.9 | I34: Open | K34: 8052440 | L34: 8052440 | M34: 8052440 | N34: IL | O34: =K34/1000000 -> 8.05244 | P34: =L34/1000000 -> 8.05244 | Q34: =M34/1000000 -> 8.05244 | R34: IL | S34: =O34*0.0036 -> 0.028988784 | T34: =P34*0.0036 -> 0.028988784 | U34: =Q34*0.0036 -> 0.028988784
A35: IL | B35: 869 | C35: Dresden Generating Station | D35: 3 | E35: 7485695 | F35: 1009 | G35: 895 | H35: 95.5 | I35: Open | K35: 7485695 | L35: 7485695 | M35: 7485695 | N35: IL | O35: =K35/1000000 -> 7.485695 | P35: =L35/1000000 -> 7.485695 | Q35: =M35/1000000 -> 7.485695 | R35: IL | S35: =O35*0.0036 -> 0.026948502 | T35: =P35*0.0036 -> 0.026948502 | U35: =Q35*0.0036 -> 0.026948502
A36: IL | B36: 6022 | C36: Braidwood Generation Station | D36: 1 | E36: 9834457 | F36: 1225 | G36: 1183 | H36: 94.9 | I36: Open | K36: 9834457 | L36: 9834457 | M36: 9834457 | N36: IL | O36: =K36/1000000 -> 9.834457 | P36: =L36/1000000 -> 9.834457 | Q36: =M36/1000000 -> 9.834457 | R36: IL | S36: =O36*0.0036 -> 0.035404045 | T36: =P36*0.0036 -> 0.035404045 | U36: =Q36*0.0036 -> 0.035404045
A37: IL | B37: 6022 | C37: Braidwood Generation Station | D37: 2 | E37: 9509002 | F37: 1225 | G37: 1154 | H37: 94.1 | I37: Open | K37: 9509002 | L37: 9509002 | M37: 9509002 | N37: IL | O37: =K37/1000000 -> 9.509002 | P37: =L37/1000000 -> 9.509002 | Q37: =M37/1000000 -> 9.509002 | R37: IL | S37: =O37*0.0036 -> 0.034232407 | T37: =P37*0.0036 -> 0.034232407 | U37: =Q37*0.0036 -> 0.034232407
A38: IL | B38: 6023 | C38: Byron Generating Station | D38: 1 | E38: 9868770 | F38: 1225 | G38: 1164 | H38: 96.8 | I38: Open | K38: 9868770 | L38: 9868770 | M38: 9868770 | N38: IL | O38: =K38/1000000 -> 9.86877 | P38: =L38/1000000 -> 9.86877 | Q38: =M38/1000000 -> 9.86877 | R38: IL | S38: =O38*0.0036 -> 0.035527572 | T38: =P38*0.0036 -> 0.035527572 | U38: =Q38*0.0036 -> 0.035527572
A39: IL | B39: 6023 | C39: Byron Generating Station | D39: 2 | E39: 10182253 | F39: 1225 | G39: 1136 | H39: 102.3 | I39: Open | K39: 10182253 | L39: 10182253 | M39: 10182253 | N39: IL | O39: =K39/1000000 -> 10.182253 | P39: =L39/1000000 -> 10.182253 | Q39: =M39/1000000 -> 10.182253 | R39: IL | S39: =O39*0.0036 -> 0.036656111 | T39: =P39*0.0036 -> 0.036656111 | U39: =Q39*0.0036 -> 0.036656111
A40: IL | B40: 6026 | C40: LaSalle Generating Station | D40: 1 | E40: 9321629 | F40: 1170 | G40: 1131 | H40: 94.1 | I40: Open | K40: 9321629 | L40: 9321629 | M40: 9321629 | N40: IL | O40: =K40/1000000 -> 9.321629 | P40: =L40/1000000 -> 9.321629 | Q40: =M40/1000000 -> 9.321629 | R40: IL | S40: =O40*0.0036 -> 0.033557864 | T40: =P40*0.0036 -> 0.033557864 | U40: =Q40*0.0036 -> 0.033557864
A41: IL | B41: 6026 | C41: LaSalle Generating Station | D41: 2 | E41: 10024137 | F41: 1170 | G41: 1134 | H41: 100.9 | I41: Open | K41: 10024137 | L41: 10024137 | M41: 10024137 | N41: IL | O41: =K41/1000000 -> 10.024137 | P41: =L41/1000000 -> 10.024137 | Q41: =M41/1000000 -> 10.024137 | R41: IL | S41: =O41*0.0036 -> 0.036086893 | T41: =P41*0.0036 -> 0.036086893 | U41: =Q41*0.0036 -> 0.036086893
...
