Workbook

Sheet res_cost_IRA
D1: From NEMS | R1: Per-unit info | T1: To GCAM | AE1: 0.2765789 | AF1: conversion from 2017$ to 1975$ | AJ1: 0.2851052 | AK1: conversion from 2015$ to 1975$
A2: Service | B2: Fuel Input | C2: Technology | D2: 2010 | E2: 2015 | F2: 2020 | G2: 2025 | H2: 2030 | I2: 2035 | J2: 2040 | K2: 2045 | L2: 2050 | M2: 2100 | N2: Unit | P2: Discount rate | Q2: Lifetime | R2: Output/yr | S2: Output unit | T2: 2010 | U2: 2015 | V2: 2020 | W2: 2025 | X2: 2030 | Y2: 2035 | Z2: 2040 | AA2: 2045 | AB2: 2050 | AC2: 2100 | AD2: Unit | AE2: lookup | AJ2: 0.2701252 | AK2: conversion from 2018$ to 1975$
A3: resid heating | B3: gas | C3: gas furnace | D3: 2497.494 | E3: 2497.494 | F3: 2497.494 | G3: 2497.494 | H3: 2497.494 | I3: 2497.494 | J3: 2497.494 | K3: 2497.494 | L3: 2497.494 | M3: 2497.494 | N3: 2017$/unit | P3: 0.15 | Q3: 18.4 | R3: 42 | S3: GJ/unit/yr | T3: =-PMT($P3,$Q3,D3)*$AE$1/$R3 -> 2.6710809 | U3: =-PMT($P3,$Q3,E3)*$AE$1/$R3 -> 2.6710809 | V3: =-PMT($P3,$Q3,F3)*$AE$1/$R3 -> 2.6710809 | W3: =-PMT($P3,$Q3,G3)*$AE$1/$R3 -> 2.6710809 | X3: =-PMT($P3,$Q3,H3)*$AE$1/$R3 -> 2.6710809 | Y3: =-PMT($P3,$Q3,I3)*$AE$1/$R3 -> 2.6710809 | Z3: =-PMT($P3,$Q3,J3)*$AE$1/$R3 -> 2.6710809 | AA3: =-PMT($P3,$Q3,K3)*$AE$1/$R3 -> 2.6710809 | ... AC3: =-PMT($P3,$Q3,M3)*$AE$1/$R3 -> 2.6710809 | AD3: 1975$/GJ | AE3: =A3&B3&C3 -> resid heatinggasgas furnace
A4: resid heating | B4: gas | C4: gas furnace hi-eff | D4: 2668 | E4: 2668 | F4: 2668 | G4: 2668 | H4: 2668 | I4: 2668 | J4: 2668 | K4: 2668 | L4: 2668 | M4: 2668 | N4: 2017$/unit | P4: 0.15 | Q4: 18.4 | R4: 42 | S4: GJ/unit/yr | T4: =-PMT($P4,$Q4,D4)*$AE$1/$R4 -> 2.8534378 | U4: =-PMT($P4,$Q4,E4)*$AE$1/$R4 -> 2.8534378 | V4: =-PMT($P4,$Q4,F4)*$AE$1/$R4 -> 2.8534378 | W4: =-PMT($P4,$Q4,G4)*$AE$1/$R4 -> 2.8534378 | X4: =-PMT($P4,$Q4,H4)*$AE$1/$R4 -> 2.8534378 | Y4: =-PMT($P4,$Q4,I4)*$AE$1/$R4 -> 2.8534378 | Z4: =-PMT($P4,$Q4,J4)*$AE$1/$R4 -> 2.8534378 | AA4: =-PMT($P4,$Q4,K4)*$AE$1/$R4 -> 2.8534378 | ... AC4: =-PMT($P4,$Q4,M4)*$AE$1/$R4 -> 2.8534378 | AD4: 1975$/GJ | AE4: =A4&B4&C4 -> resid heatinggasgas furnace hi-eff
A5: resid heating | B5: electricity | C5: electric furnace | D5: 1100 | E5: 1100 | F5: 1100 | G5: 1100 | H5: 1100 | I5: 1100 | J5: 1100 | K5: 1100 | L5: 1100 | M5: 1100 | N5: 2017$/unit | P5: 0.15 | Q5: 18.4 | R5: 42 | S5: GJ/unit/yr | T5: =-PMT($P5,$Q5,D5)*$AE$1/$R5 -> 1.1764549 | U5: =-PMT($P5,$Q5,E5)*$AE$1/$R5 -> 1.1764549 | V5: =-PMT($P5,$Q5,F5)*$AE$1/$R5 -> 1.1764549 | W5: =-PMT($P5,$Q5,G5)*$AE$1/$R5 -> 1.1764549 | X5: =-PMT($P5,$Q5,H5)*$AE$1/$R5 -> 1.1764549 | Y5: =-PMT($P5,$Q5,I5)*$AE$1/$R5 -> 1.1764549 | Z5: =-PMT($P5,$Q5,J5)*$AE$1/$R5 -> 1.1764549 | AA5: =-PMT($P5,$Q5,K5)*$AE$1/$R5 -> 1.1764549 | ... AC5: =-PMT($P5,$Q5,M5)*$AE$1/$R5 -> 1.1764549 | AD5: 1975$/GJ | AE5: =A5&B5&C5 -> resid heatingelectricityelectric furnace
A6: resid heating | B6: electricity | C6: electric heat pump | D6: =$C47 -> 3659.2067 | E6: =$C47 -> 3659.2067 | F6: =$C47 -> 3659.2067 | G6: =$C47 -> 3659.2067 | H6: =$C47 -> 3659.2067 | I6: =$C47 -> 3659.2067 | J6: =$C47 -> 3659.2067 | K6: =$C47 -> 3659.2067 | ... M6: =$C47 -> 3659.2067 | N6: 2017$/unit | P6: 0.15 | Q6: 18.4 | R6: 42 | S6: GJ/unit/yr | T6: =-PMT($P6,$Q6,D6)*$AE$1/$R6 -> 3.9135377 | U6: =-PMT($P6,$Q6,E6)*$AE$1/$R6 -> 3.9135377 | V6: =-PMT($P6,$Q6,F6)*$AE$1/$R6 -> 3.9135377 | W6: =-PMT($P6,$Q6,G6)*$AE$1/$R6 -> 3.9135377 | X6: =-PMT($P6,$Q6,H6)*$AE$1/$R6 -> 3.9135377 | Y6: =-PMT($P6,$Q6,I6)*$AE$1/$R6 -> 3.9135377 | Z6: =-PMT($P6,$Q6,J6)*$AE$1/$R6 -> 3.9135377 | AA6: =-PMT($P6,$Q6,K6)*$AE$1/$R6 -> 3.9135377 | ... AC6: =-PMT($P6,$Q6,M6)*$AE$1/$R6 -> 3.9135377 | AD6: 1975$/GJ | AE6: =A6&B6&C6 -> resid heatingelectricityelectric heat pump
A7: resid heating | B7: refined liquids | C7: fuel furnace | D7: 4225 | E7: 4225 | F7: 4225 | G7: 4225 | H7: 4225 | I7: 4225 | J7: 4225 | K7: 4225 | L7: 4225 | M7: 4225 | N7: 2017$/unit | P7: 0.15 | Q7: 18.4 | R7: 42 | S7: GJ/unit/yr | T7: =-PMT($P7,$Q7,D7)*$AE$1/$R7 -> 4.5186561 | U7: =-PMT($P7,$Q7,E7)*$AE$1/$R7 -> 4.5186561 | V7: =-PMT($P7,$Q7,F7)*$AE$1/$R7 -> 4.5186561 | W7: =-PMT($P7,$Q7,G7)*$AE$1/$R7 -> 4.5186561 | X7: =-PMT($P7,$Q7,H7)*$AE$1/$R7 -> 4.5186561 | Y7: =-PMT($P7,$Q7,I7)*$AE$1/$R7 -> 4.5186561 | Z7: =-PMT($P7,$Q7,J7)*$AE$1/$R7 -> 4.5186561 | AA7: =-PMT($P7,$Q7,K7)*$AE$1/$R7 -> 4.5186561 | ... AC7: =-PMT($P7,$Q7,M7)*$AE$1/$R7 -> 4.5186561 | AD7: 1975$/GJ | AE7: =A7&B7&C7 -> resid heatingrefined liquidsfuel furnace
A8: resid heating | B8: refined liquids | C8: fuel furnace hi-eff | D8: 4350 | E8: 4350 | F8: 4350 | G8: 4350 | H8: 4350 | I8: 4350 | J8: 4350 | K8: 4350 | L8: 4350 | M8: 4350 | N8: 2017$/unit | P8: 0.15 | Q8: 18.4 | R8: 42 | S8: GJ/unit/yr | T8: =-PMT($P8,$Q8,D8)*$AE$1/$R8 -> 4.6523442 | U8: =-PMT($P8,$Q8,E8)*$AE$1/$R8 -> 4.6523442 | V8: =-PMT($P8,$Q8,F8)*$AE$1/$R8 -> 4.6523442 | W8: =-PMT($P8,$Q8,G8)*$AE$1/$R8 -> 4.6523442 | X8: =-PMT($P8,$Q8,H8)*$AE$1/$R8 -> 4.6523442 | Y8: =-PMT($P8,$Q8,I8)*$AE$1/$R8 -> 4.6523442 | Z8: =-PMT($P8,$Q8,J8)*$AE$1/$R8 -> 4.6523442 | AA8: =-PMT($P8,$Q8,K8)*$AE$1/$R8 -> 4.6523442 | ... AC8: =-PMT($P8,$Q8,M8)*$AE$1/$R8 -> 4.6523442 | AD8: 1975$/GJ | AE8: =A8&B8&C8 -> resid heatingrefined liquidsfuel furnace hi-eff
A9: resid cooling | B9: electricity | C9: air conditioning | D9: 3680.2768 | E9: 3680.2768 | F9: 3680.2768 | G9: 3942.2146 | H9: 3942.2146 | I9: 3942.2146 | J9: 3942.2146 | K9: 3942.2146 | L9: 3942.2146 | M9: 3942.2146 | N9: 2017$/unit | P9: 0.15 | Q9: 18.4 | R9: 19 | S9: GJ/unit/yr | T9: =-PMT($P9,$Q9,D9)*$AE$1/$R9 -> 8.7007914 | U9: =-PMT($P9,$Q9,E9)*$AE$1/$R9 -> 8.7007914 | V9: =-PMT($P9,$Q9,F9)*$AE$1/$R9 -> 8.7007914 | W9: =-PMT($P9,$Q9,G9)*$AE$1/$R9 -> 9.3200562 | X9: =-PMT($P9,$Q9,H9)*$AE$1/$R9 -> 9.3200562 | Y9: =-PMT($P9,$Q9,I9)*$AE$1/$R9 -> 9.3200562 | Z9: =-PMT($P9,$Q9,J9)*$AE$1/$R9 -> 9.3200562 | AA9: =-PMT($P9,$Q9,K9)*$AE$1/$R9 -> 9.3200562 | ... AC9: =-PMT($P9,$Q9,M9)*$AE$1/$R9 -> 9.3200562 | AD9: 1975$/GJ | AE9: =A9&B9&C9 -> resid coolingelectricityair conditioning
A10: resid cooling | B10: electricity | C10: air conditioning hi-eff | D10: =$C50 -> 1463.6827 | E10: =$C50 -> 1463.6827 | F10: =$C50 -> 1463.6827 | G10: =$C50 -> 1463.6827 | H10: =$C50 -> 1463.6827 | I10: =$C50 -> 1463.6827 | J10: =$C50 -> 1463.6827 | K10: =$C50 -> 1463.6827 | ... M10: =$C50 -> 1463.6827 | N10: 2017$/unit | P10: 0.15 | Q10: 18.4 | R10: 19 | S10: GJ/unit/yr | T10: =-PMT($P10,$Q10,D10)*$AE$1/$R10 -> 3.4603912 | U10: =-PMT($P10,$Q10,E10)*$AE$1/$R10 -> 3.4603912 | V10: =-PMT($P10,$Q10,F10)*$AE$1/$R10 -> 3.4603912 | W10: =-PMT($P10,$Q10,G10)*$AE$1/$R10 -> 3.4603912 | X10: =-PMT($P10,$Q10,H10)*$AE$1/$R10 -> 3.4603912 | Y10: =-PMT($P10,$Q10,I10)*$AE$1/$R10 -> 3.4603912 | Z10: =-PMT($P10,$Q10,J10)*$AE$1/$R10 -> 3.4603912 | AA10: =-PMT($P10,$Q10,K10)*$AE$1/$R10 -> 3.4603912 | ... AC10: =-PMT($P10,$Q10,M10)*$AE$1/$R10 -> 3.4603912 | AD10: 1975$/GJ | AE10: =A10&B10&C10 -> resid coolingelectricityair conditioning hi-eff
A11: resid hot water | B11: gas | C11: gas water heater | D11: 1925 | E11: 1925 | F11: 1925 | G11: 1925 | H11: 1925 | I11: 1925 | J11: 1925 | K11: 1925 | L11: 1925 | M11: 1925 | N11: 2017$/unit | P11: 0.25 | Q11: 9 | R11: 9 | S11: GJ/unit/yr | T11: =-PMT($P11,$Q11,D11)*$AE$1/$R11 -> 17.081995 | U11: =-PMT($P11,$Q11,E11)*$AE$1/$R11 -> 17.081995 | V11: =-PMT($P11,$Q11,F11)*$AE$1/$R11 -> 17.081995 | W11: =-PMT($P11,$Q11,G11)*$AE$1/$R11 -> 17.081995 | X11: =-PMT($P11,$Q11,H11)*$AE$1/$R11 -> 17.081995 | Y11: =-PMT($P11,$Q11,I11)*$AE$1/$R11 -> 17.081995 | Z11: =-PMT($P11,$Q11,J11)*$AE$1/$R11 -> 17.081995 | AA11: =-PMT($P11,$Q11,K11)*$AE$1/$R11 -> 17.081995 | ... AC11: =-PMT($P11,$Q11,M11)*$AE$1/$R11 -> 17.081995 | AD11: 1975$/GJ | AE11: =A11&B11&C11 -> resid hot watergasgas water heater
A12: resid hot water | B12: gas | C12: gas water heater hi-eff | D12: 2025 | E12: 2025 | F12: 2025 | G12: 2025 | H12: 2025 | I12: 2025 | J12: 2025 | K12: 2025 | L12: 2025 | M12: 2025 | N12: 2017$/unit | P12: 0.25 | Q12: 9 | R12: 9 | S12: GJ/unit/yr | T12: =-PMT($P12,$Q12,D12)*$AE$1/$R12 -> 17.969371 | U12: =-PMT($P12,$Q12,E12)*$AE$1/$R12 -> 17.969371 | V12: =-PMT($P12,$Q12,F12)*$AE$1/$R12 -> 17.969371 | W12: =-PMT($P12,$Q12,G12)*$AE$1/$R12 -> 17.969371 | X12: =-PMT($P12,$Q12,H12)*$AE$1/$R12 -> 17.969371 | Y12: =-PMT($P12,$Q12,I12)*$AE$1/$R12 -> 17.969371 | Z12: =-PMT($P12,$Q12,J12)*$AE$1/$R12 -> 17.969371 | AA12: =-PMT($P12,$Q12,K12)*$AE$1/$R12 -> 17.969371 | ... AC12: =-PMT($P12,$Q12,M12)*$AE$1/$R12 -> 17.969371 | AD12: 1975$/GJ | AE12: =A12&B12&C12 -> resid hot watergasgas water heater hi-eff
A13: resid hot water | B13: electricity | C13: electric heat pump water heater | D13: =$C46 -> 1600.9029 | E13: =$C46 -> 1600.9029 | F13: =$C46 -> 1600.9029 | G13: =$C46 -> 1600.9029 | H13: =$C46 -> 1600.9029 | I13: =$C46 -> 1600.9029 | J13: =$C46 -> 1600.9029 | K13: =$C46 -> 1600.9029 | ... M13: =$C46 -> 1600.9029 | N13: 2017$/unit | P13: 0.25 | Q13: 14 | R13: 9 | S13: GJ/unit/yr | T13: =-PMT($P13,$Q13,D13)*$AE$1/$R13 -> 12.865148 | U13: =-PMT($P13,$Q13,E13)*$AE$1/$R13 -> 12.865148 | V13: =-PMT($P13,$Q13,F13)*$AE$1/$R13 -> 12.865148 | W13: =-PMT($P13,$Q13,G13)*$AE$1/$R13 -> 12.865148 | X13: =-PMT($P13,$Q13,H13)*$AE$1/$R13 -> 12.865148 | Y13: =-PMT($P13,$Q13,I13)*$AE$1/$R13 -> 12.865148 | Z13: =-PMT($P13,$Q13,J13)*$AE$1/$R13 -> 12.865148 | AA13: =-PMT($P13,$Q13,K13)*$AE$1/$R13 -> 12.865148 | ... AC13: =-PMT($P13,$Q13,M13)*$AE$1/$R13 -> 12.865148 | AD13: 1975$/GJ | AE13: =A13&B13&C13 -> resid hot waterelectricityelectric heat pump water heater
A14: resid hot water | B14: electricity | C14: electric resistance water heater | D14: 850 | E14: 850 | F14: 850 | G14: 850 | H14: 850 | I14: 850 | J14: 850 | K14: 850 | L14: 850 | M14: 850 | N14: 2017$/unit | P14: 0.25 | Q14: 14 | R14: 9 | S14: GJ/unit/yr | T14: =-PMT($P14,$Q14,D14)*$AE$1/$R14 -> 6.8307549 | U14: =-PMT($P14,$Q14,E14)*$AE$1/$R14 -> 6.8307549 | V14: =-PMT($P14,$Q14,F14)*$AE$1/$R14 -> 6.8307549 | W14: =-PMT($P14,$Q14,G14)*$AE$1/$R14 -> 6.8307549 | X14: =-PMT($P14,$Q14,H14)*$AE$1/$R14 -> 6.8307549 | Y14: =-PMT($P14,$Q14,I14)*$AE$1/$R14 -> 6.8307549 | Z14: =-PMT($P14,$Q14,J14)*$AE$1/$R14 -> 6.8307549 | AA14: =-PMT($P14,$Q14,K14)*$AE$1/$R14 -> 6.8307549 | ... AC14: =-PMT($P14,$Q14,M14)*$AE$1/$R14 -> 6.8307549 | AD14: 1975$/GJ | AE14: =A14&B14&C14 -> resid hot waterelectricityelectric resistance water heater
A15: resid hot water | B15: electricity | C15: electric resistance water heater hi-eff | D15: 2075 | E15: 2075 | F15: 2075 | G15: 2075 | H15: 2075 | I15: 2075 | J15: 2075 | K15: 2075 | L15: 2075 | M15: 2075 | N15: 2017$/unit | P15: 0.25 | Q15: 14 | R15: 9 | S15: GJ/unit/yr | T15: =-PMT($P15,$Q15,D15)*$AE$1/$R15 -> 16.675078 | U15: =-PMT($P15,$Q15,E15)*$AE$1/$R15 -> 16.675078 | V15: =-PMT($P15,$Q15,F15)*$AE$1/$R15 -> 16.675078 | W15: =-PMT($P15,$Q15,G15)*$AE$1/$R15 -> 16.675078 | X15: =-PMT($P15,$Q15,H15)*$AE$1/$R15 -> 16.675078 | Y15: =-PMT($P15,$Q15,I15)*$AE$1/$R15 -> 16.675078 | Z15: =-PMT($P15,$Q15,J15)*$AE$1/$R15 -> 16.675078 | AA15: =-PMT($P15,$Q15,K15)*$AE$1/$R15 -> 16.675078 | ... AC15: =-PMT($P15,$Q15,M15)*$AE$1/$R15 -> 16.675078 | AD15: 1975$/GJ | AE15: =A15&B15&C15 -> resid hot waterelectricityelectric resistance water heater hi-eff
A16: resid hot water | B16: refined liquids | C16: fuel water heater | D16: 1925 | E16: 1925 | F16: 1925 | G16: 1925 | H16: 1925 | I16: 1925 | J16: 1925 | K16: 1925 | L16: 1925 | M16: 1925 | N16: 2017$/unit | P16: 0.25 | Q16: 9 | R16: 9 | S16: GJ/unit/yr | T16: =-PMT($P16,$Q16,D16)*$AE$1/$R16 -> 17.081995 | U16: =-PMT($P16,$Q16,E16)*$AE$1/$R16 -> 17.081995 | V16: =-PMT($P16,$Q16,F16)*$AE$1/$R16 -> 17.081995 | W16: =-PMT($P16,$Q16,G16)*$AE$1/$R16 -> 17.081995 | X16: =-PMT($P16,$Q16,H16)*$AE$1/$R16 -> 17.081995 | Y16: =-PMT($P16,$Q16,I16)*$AE$1/$R16 -> 17.081995 | Z16: =-PMT($P16,$Q16,J16)*$AE$1/$R16 -> 17.081995 | AA16: =-PMT($P16,$Q16,K16)*$AE$1/$R16 -> 17.081995 | ... AC16: =-PMT($P16,$Q16,M16)*$AE$1/$R16 -> 17.081995 | AD16: 1975$/GJ | AE16: =A16&B16&C16 -> resid hot waterrefined liquidsfuel water heater
A17: resid hot water | B17: refined liquids | C17: fuel water heater hi-eff | D17: 1925 | E17: 1925 | F17: 1925 | G17: 1925 | H17: 1925 | I17: 1925 | J17: 1925 | K17: 1925 | L17: 1925 | M17: 1925 | N17: 2017$/unit | P17: 0.25 | Q17: 9 | R17: 9 | S17: GJ/unit/yr | T17: =-PMT($P17,$Q17,D17)*$AE$1/$R17 -> 17.081995 | U17: =-PMT($P17,$Q17,E17)*$AE$1/$R17 -> 17.081995 | V17: =-PMT($P17,$Q17,F17)*$AE$1/$R17 -> 17.081995 | W17: =-PMT($P17,$Q17,G17)*$AE$1/$R17 -> 17.081995 | X17: =-PMT($P17,$Q17,H17)*$AE$1/$R17 -> 17.081995 | Y17: =-PMT($P17,$Q17,I17)*$AE$1/$R17 -> 17.081995 | Z17: =-PMT($P17,$Q17,J17)*$AE$1/$R17 -> 17.081995 | AA17: =-PMT($P17,$Q17,K17)*$AE$1/$R17 -> 17.081995 | ... AC17: =-PMT($P17,$Q17,M17)*$AE$1/$R17 -> 17.081995 | AD17: 1975$/GJ | AE17: =A17&B17&C17 -> resid hot waterrefined liquidsfuel water heater hi-eff
A18: resid refrigerators | B18: electricity | C18: refrigerator | D18: 1096.6667 | E18: 1096.6667 | F18: 1096.6667 | G18: 1096.6667 | H18: 1096.6667 | I18: 1096.6667 | J18: 1096.6667 | K18: 1096.6667 | L18: 1096.6667 | M18: 1096.6667 | N18: 2017$/unit | P18: 0.15 | Q18: 19 | R18: =res_eff!D18*res_eff!P18*0.0036 -> 3.696 | S18: GJ/unit/yr | T18: =-PMT($P18,$Q18,D18)*$AE$1/$R18 -> 13.240182 | U18: =-PMT($P18,$Q18,E18)*$AE$1/$R18 -> 13.240182 | V18: =-PMT($P18,$Q18,F18)*$AE$1/$R18 -> 13.240182 | W18: =-PMT($P18,$Q18,G18)*$AE$1/$R18 -> 13.240182 | X18: =-PMT($P18,$Q18,H18)*$AE$1/$R18 -> 13.240182 | Y18: =-PMT($P18,$Q18,I18)*$AE$1/$R18 -> 13.240182 | Z18: =-PMT($P18,$Q18,J18)*$AE$1/$R18 -> 13.240182 | AA18: =-PMT($P18,$Q18,K18)*$AE$1/$R18 -> 13.240182 | ... AC18: =-PMT($P18,$Q18,M18)*$AE$1/$R18 -> 13.240182 | AD18: 1975$/GJ | AE18: =A18&B18&C18 -> resid refrigeratorselectricityrefrigerator
A19: resid refrigerators | B19: electricity | C19: refrigerator hi-eff | D19: 1186.67 | E19: 1186.67 | F19: 1186.67 | G19: 1186.67 | H19: 1186.67 | I19: 1186.67 | J19: 1186.67 | K19: 1186.67 | L19: 1186.67 | M19: 1186.67 | N19: 2017$/unit | P19: 0.15 | Q19: 19 | R19: =R18 -> 3.696 | S19: GJ/unit/yr | T19: =-PMT($P19,$Q19,D19)*$AE$1/$R19 -> 14.326803 | U19: =-PMT($P19,$Q19,E19)*$AE$1/$R19 -> 14.326803 | V19: =-PMT($P19,$Q19,F19)*$AE$1/$R19 -> 14.326803 | W19: =-PMT($P19,$Q19,G19)*$AE$1/$R19 -> 14.326803 | X19: =-PMT($P19,$Q19,H19)*$AE$1/$R19 -> 14.326803 | Y19: =-PMT($P19,$Q19,I19)*$AE$1/$R19 -> 14.326803 | Z19: =-PMT($P19,$Q19,J19)*$AE$1/$R19 -> 14.326803 | AA19: =-PMT($P19,$Q19,K19)*$AE$1/$R19 -> 14.326803 | ... AC19: =-PMT($P19,$Q19,M19)*$AE$1/$R19 -> 14.326803 | AD19: 1975$/GJ | AE19: =A19&B19&C19 -> resid refrigeratorselectricityrefrigerator hi-eff
A20: resid cooking | B20: gas | C20: gas oven | D20: 370 | E20: 370 | F20: 370 | G20: 370 | H20: 370 | I20: 370 | J20: 370 | K20: 370 | L20: 370 | M20: 370 | N20: 2017$/unit | P20: 0.15 | Q20: 19 | R20: =$R$22 -> 0.79765211 | S20: GJ/unit/yr | T20: =-PMT($P20,$Q20,D20)*$AE$1/$R20 -> 20.698529 | U20: =-PMT($P20,$Q20,E20)*$AE$1/$R20 -> 20.698529 | V20: =-PMT($P20,$Q20,F20)*$AE$1/$R20 -> 20.698529 | W20: =-PMT($P20,$Q20,G20)*$AE$1/$R20 -> 20.698529 | X20: =-PMT($P20,$Q20,H20)*$AE$1/$R20 -> 20.698529 | Y20: =-PMT($P20,$Q20,I20)*$AE$1/$R20 -> 20.698529 | Z20: =-PMT($P20,$Q20,J20)*$AE$1/$R20 -> 20.698529 | AA20: =-PMT($P20,$Q20,K20)*$AE$1/$R20 -> 20.698529 | ... AC20: =-PMT($P20,$Q20,M20)*$AE$1/$R20 -> 20.698529 | AD20: 1975$/GJ | AE20: =A20&B20&C20 -> resid cookinggasgas oven
A21: resid cooking | B21: gas | C21: gas oven hi-eff | D21: 370 | E21: 370 | F21: 370 | G21: 370 | H21: 370 | I21: 370 | J21: 370 | K21: 370 | L21: 370 | M21: 370 | N21: 2017$/unit | P21: 0.15 | Q21: 19 | R21: =$R$22 -> 0.79765211 | S21: GJ/unit/yr | T21: =-PMT($P21,$Q21,D21)*$AE$1/$R21 -> 20.698529 | U21: =-PMT($P21,$Q21,E21)*$AE$1/$R21 -> 20.698529 | V21: =-PMT($P21,$Q21,F21)*$AE$1/$R21 -> 20.698529 | W21: =-PMT($P21,$Q21,G21)*$AE$1/$R21 -> 20.698529 | X21: =-PMT($P21,$Q21,H21)*$AE$1/$R21 -> 20.698529 | Y21: =-PMT($P21,$Q21,I21)*$AE$1/$R21 -> 20.698529 | Z21: =-PMT($P21,$Q21,J21)*$AE$1/$R21 -> 20.698529 | AA21: =-PMT($P21,$Q21,K21)*$AE$1/$R21 -> 20.698529 | ... AC21: =-PMT($P21,$Q21,M21)*$AE$1/$R21 -> 20.698529 | AD21: 1975$/GJ | AE21: =A21&B21&C21 -> resid cookinggasgas oven hi-eff
A22: resid cooking | B22: electricity | C22: electric oven | D22: =$C48 -> 384.2167 | E22: =$C48 -> 384.2167 | F22: =$C48 -> 384.2167 | G22: =$C48 -> 384.2167 | H22: =$C48 -> 384.2167 | I22: =$C48 -> 384.2167 | J22: =$C48 -> 384.2167 | K22: =$C48 -> 384.2167 | ... M22: =$C48 -> 384.2167 | N22: 2017$/unit | P22: 0.15 | Q22: 19 | R22: =res_eff!D22*res_eff!P22*0.0036 -> 0.79765211 | S22: GJ/unit/yr | T22: =-PMT($P22,$Q22,D22)*$AE$1/$R22 -> 21.493839 | U22: =-PMT($P22,$Q22,E22)*$AE$1/$R22 -> 21.493839 | V22: =-PMT($P22,$Q22,F22)*$AE$1/$R22 -> 21.493839 | W22: =-PMT($P22,$Q22,G22)*$AE$1/$R22 -> 21.493839 | X22: =-PMT($P22,$Q22,H22)*$AE$1/$R22 -> 21.493839 | Y22: =-PMT($P22,$Q22,I22)*$AE$1/$R22 -> 21.493839 | Z22: =-PMT($P22,$Q22,J22)*$AE$1/$R22 -> 21.493839 | AA22: =-PMT($P22,$Q22,K22)*$AE$1/$R22 -> 21.493839 | ... AC22: =-PMT($P22,$Q22,M22)*$AE$1/$R22 -> 21.493839 | AD22: 1975$/GJ | AE22: =A22&B22&C22 -> resid cookingelectricityelectric oven
A23: resid clothes dryers | B23: gas | C23: clothes dryer | D23: 660 | E23: 660 | F23: 660 | G23: 660 | H23: 660 | I23: 660 | J23: 660 | K23: 660 | L23: 660 | M23: 660 | N23: 2017$/unit | P23: 0.15 | Q23: 10 | R23: =res_eff!D25*res_eff!P25*0.454 -> 1018.776 | S23: kg/unit/yr | T23: =-PMT($P23,$Q23,D23)*$AE$1/$R23 -> 0.035701552 | U23: =-PMT($P23,$Q23,E23)*$AE$1/$R23 -> 0.035701552 | V23: =-PMT($P23,$Q23,F23)*$AE$1/$R23 -> 0.035701552 | W23: =-PMT($P23,$Q23,G23)*$AE$1/$R23 -> 0.035701552 | X23: =-PMT($P23,$Q23,H23)*$AE$1/$R23 -> 0.035701552 | Y23: =-PMT($P23,$Q23,I23)*$AE$1/$R23 -> 0.035701552 | Z23: =-PMT($P23,$Q23,J23)*$AE$1/$R23 -> 0.035701552 | AA23: =-PMT($P23,$Q23,K23)*$AE$1/$R23 -> 0.035701552 | ... AC23: =-PMT($P23,$Q23,M23)*$AE$1/$R23 -> 0.035701552 | AD23: 1975$/kg | AE23: =A23&B23&C23 -> resid clothes dryersgasclothes dryer
A24: resid clothes dryers | B24: gas | C24: clothes dryer | D24: 660 | E24: 660 | F24: 660 | G24: 660 | H24: 660 | I24: 660 | J24: 660 | K24: 660 | L24: 660 | M24: 660 | N24: 2017$/unit | P24: 0.15 | Q24: 10 | R24: =$R$23 -> 1018.776 | S24: kg/unit/yr | T24: =-PMT($P24,$Q24,D24)*$AE$1/$R24 -> 0.035701552 | U24: =-PMT($P24,$Q24,E24)*$AE$1/$R24 -> 0.035701552 | V24: =-PMT($P24,$Q24,F24)*$AE$1/$R24 -> 0.035701552 | W24: =-PMT($P24,$Q24,G24)*$AE$1/$R24 -> 0.035701552 | X24: =-PMT($P24,$Q24,H24)*$AE$1/$R24 -> 0.035701552 | Y24: =-PMT($P24,$Q24,I24)*$AE$1/$R24 -> 0.035701552 | Z24: =-PMT($P24,$Q24,J24)*$AE$1/$R24 -> 0.035701552 | AA24: =-PMT($P24,$Q24,K24)*$AE$1/$R24 -> 0.035701552 | ... AC24: =-PMT($P24,$Q24,M24)*$AE$1/$R24 -> 0.035701552 | AD24: 1975$/kg | AE24: =A24&B24&C24 -> resid clothes dryersgasclothes dryer
A25: resid clothes dryers | B25: electricity | C25: clothes dryer | D25: 540 | E25: 540 | F25: 540 | G25: 540 | H25: 540 | I25: 540 | J25: 540 | K25: 540 | L25: 540 | M25: 540 | N25: 2017$/unit | P25: 0.15 | Q25: 10 | R25: =$R$23 -> 1018.776 | S25: kg/unit/yr | T25: =-PMT($P25,$Q25,D25)*$AE$1/$R25 -> 0.029210361 | U25: =-PMT($P25,$Q25,E25)*$AE$1/$R25 -> 0.029210361 | V25: =-PMT($P25,$Q25,F25)*$AE$1/$R25 -> 0.029210361 | W25: =-PMT($P25,$Q25,G25)*$AE$1/$R25 -> 0.029210361 | X25: =-PMT($P25,$Q25,H25)*$AE$1/$R25 -> 0.029210361 | Y25: =-PMT($P25,$Q25,I25)*$AE$1/$R25 -> 0.029210361 | Z25: =-PMT($P25,$Q25,J25)*$AE$1/$R25 -> 0.029210361 | AA25: =-PMT($P25,$Q25,K25)*$AE$1/$R25 -> 0.029210361 | ... AC25: =-PMT($P25,$Q25,M25)*$AE$1/$R25 -> 0.029210361 | AD25: 1975$/kg | AE25: =A25&B25&C25 -> resid clothes dryerselectricityclothes dryer
A26: resid clothes dryers | B26: electricity | C26: clothes dryer hi-eff | D26: =$C48 -> 384.2167 | E26: =$C48 -> 384.2167 | F26: =$C48 -> 384.2167 | G26: =$C48 -> 384.2167 | H26: =$C48 -> 384.2167 | I26: =$C48 -> 384.2167 | J26: =$C48 -> 384.2167 | K26: =$C48 -> 384.2167 | ... M26: =$C48 -> 384.2167 | N26: 2017$/unit | P26: 0.15 | Q26: 10 | R26: =$R$23 -> 1018.776 | S26: kg/unit/yr | T26: =-PMT($P26,$Q26,D26)*$AE$1/$R26 -> 0.020783534 | U26: =-PMT($P26,$Q26,E26)*$AE$1/$R26 -> 0.020783534 | V26: =-PMT($P26,$Q26,F26)*$AE$1/$R26 -> 0.020783534 | W26: =-PMT($P26,$Q26,G26)*$AE$1/$R26 -> 0.020783534 | X26: =-PMT($P26,$Q26,H26)*$AE$1/$R26 -> 0.020783534 | Y26: =-PMT($P26,$Q26,I26)*$AE$1/$R26 -> 0.020783534 | Z26: =-PMT($P26,$Q26,J26)*$AE$1/$R26 -> 0.020783534 | AA26: =-PMT($P26,$Q26,K26)*$AE$1/$R26 -> 0.020783534 | ... AC26: =-PMT($P26,$Q26,M26)*$AE$1/$R26 -> 0.020783534 | AD26: 1975$/kg | AE26: =A26&B26&C26 -> resid clothes dryerselectricityclothes dryer hi-eff
A27: resid freezers | B27: electricity | C27: freezer | D27: 625 | E27: 625 | F27: 625 | G27: 625 | H27: 625 | I27: 625 | J27: 625 | K27: 625 | L27: 625 | M27: 625 | N27: 2017$/unit | P27: 0.15 | Q27: 10 | R27: =res_eff!D27*res_eff!P27*0.0036 -> 1.3374 | S27: GJ/unit/yr | T27: =-PMT($P27,$Q27,D27)*$AE$1/$R27 -> 25.753756 | U27: =-PMT($P27,$Q27,E27)*$AE$1/$R27 -> 25.753756 | V27: =-PMT($P27,$Q27,F27)*$AE$1/$R27 -> 25.753756 | W27: =-PMT($P27,$Q27,G27)*$AE$1/$R27 -> 25.753756 | X27: =-PMT($P27,$Q27,H27)*$AE$1/$R27 -> 25.753756 | Y27: =-PMT($P27,$Q27,I27)*$AE$1/$R27 -> 25.753756 | Z27: =-PMT($P27,$Q27,J27)*$AE$1/$R27 -> 25.753756 | AA27: =-PMT($P27,$Q27,K27)*$AE$1/$R27 -> 25.753756 | ... AC27: =-PMT($P27,$Q27,M27)*$AE$1/$R27 -> 25.753756 | AD27: 1975$/GJ | AE27: =A27&B27&C27 -> resid freezerselectricityfreezer
A28: resid freezers | B28: electricity | C28: freezer hi-eff | D28: 625 | E28: 625 | F28: 625 | G28: 625 | H28: 625 | I28: 625 | J28: 625 | K28: 625 | L28: 625 | M28: 625 | N28: 2017$/unit | P28: 0.15 | Q28: 10 | R28: =R27 -> 1.3374 | S28: GJ/unit/yr | T28: =-PMT($P28,$Q28,D28)*$AE$1/$R28 -> 25.753756 | U28: =-PMT($P28,$Q28,E28)*$AE$1/$R28 -> 25.753756 | V28: =-PMT($P28,$Q28,F28)*$AE$1/$R28 -> 25.753756 | W28: =-PMT($P28,$Q28,G28)*$AE$1/$R28 -> 25.753756 | X28: =-PMT($P28,$Q28,H28)*$AE$1/$R28 -> 25.753756 | Y28: =-PMT($P28,$Q28,I28)*$AE$1/$R28 -> 25.753756 | Z28: =-PMT($P28,$Q28,J28)*$AE$1/$R28 -> 25.753756 | AA28: =-PMT($P28,$Q28,K28)*$AE$1/$R28 -> 25.753756 | ... AC28: =-PMT($P28,$Q28,M28)*$AE$1/$R28 -> 25.753756 | AD28: 1975$/GJ | AE28: =A28&B28&C28 -> resid freezerselectricityfreezer hi-eff
A29: resid lighting | B29: electricity | C29: incandescent | D29: 1.99 | E29: 1.99 | F29: 1.99 | G29: 1.99 | H29: 1.99 | I29: 1.99 | J29: 1.99 | K29: 1.99 | L29: 1.99 | M29: 1.99 | N29: 2017$/unit | P29: 0.15 | Q29: =[1]rsmlgt_AT15!$G$38/8760/0.1 -> 1.1415525 | R29: =[1]rsmlgt_AT15!$F$36*res_eff!D29*8760*0.1/1000000 -> 0.8688168 | S29: mil lumen-hours/unit/yr | T29: =-PMT($P29,$Q29,D29)*$AE$1/$R29 -> 0.64436911 | U29: =-PMT($P29,$Q29,E29)*$AE$1/$R29 -> 0.64436911 | V29: =-PMT($P29,$Q29,F29)*$AE$1/$R29 -> 0.64436911 | W29: =-PMT($P29,$Q29,G29)*$AE$1/$R29 -> 0.64436911 | X29: =-PMT($P29,$Q29,H29)*$AE$1/$R29 -> 0.64436911 | Y29: =-PMT($P29,$Q29,I29)*$AE$1/$R29 -> 0.64436911 | Z29: =-PMT($P29,$Q29,J29)*$AE$1/$R29 -> 0.64436911 | AA29: =-PMT($P29,$Q29,K29)*$AE$1/$R29 -> 0.64436911 | ... AC29: =-PMT($P29,$Q29,M29)*$AE$1/$R29 -> 0.64436911 | AD29: 1975$/mil lumen-hr | AE29: =A29&B29&C29 -> resid lightingelectricityincandescent
A30: resid lighting | B30: electricity | C30: fluorescent | D30: 1.98 | E30: 1.98 | F30: 1.98 | G30: 1.98 | H30: 1.89 | I30: 1.89 | J30: 1.79 | K30: 1.79 | L30: 1.79 | M30: 1.79 | N30: 2017$/unit | P30: 0.15 | Q30: =[1]rsmlgt_AT15!$G$41/8760/0.1 -> 11.415525 | R30: =$R$29 -> 0.8688168 | S30: mil lumen-hours/unit/yr | T30: =-PMT($P30,$Q30,D30)*$AE$1/$R30 -> 0.1186011 | U30: =-PMT($P30,$Q30,E30)*$AE$1/$R30 -> 0.1186011 | V30: =-PMT($P30,$Q30,F30)*$AE$1/$R30 -> 0.1186011 | W30: =-PMT($P30,$Q30,G30)*$AE$1/$R30 -> 0.1186011 | X30: =-PMT($P30,$Q30,H30)*$AE$1/$R30 -> 0.11321014 | Y30: =-PMT($P30,$Q30,I30)*$AE$1/$R30 -> 0.11321014 | Z30: =-PMT($P30,$Q30,J30)*$AE$1/$R30 -> 0.10722019 | AA30: =-PMT($P30,$Q30,K30)*$AE$1/$R30 -> 0.10722019 | ... AC30: =-PMT($P30,$Q30,M30)*$AE$1/$R30 -> 0.10722019 | AD30: 1975$/mil lumen-hr | AE30: =A30&B30&C30 -> resid lightingelectricityfluorescent
A31: resid lighting | B31: electricity | C31: solid state | D31: 1.24 | E31: 1.24 | F31: 1.24 | G31: 0.94 | H31: 0.63 | I31: 0.63 | J31: 0.42 | K31: 0.42 | L31: 0.42 | M31: 0.42 | N31: 2017$/unit | P31: 0.15 | Q31: =[1]rsmlgt_AT15!$G$50/8760/0.1 -> 38.835616 | R31: =$R$29 -> 0.8688168 | S31: mil lumen-hours/unit/yr | T31: =-PMT($P31,$Q31,D31)*$AE$1/$R31 -> 0.059472452 | U31: =-PMT($P31,$Q31,E31)*$AE$1/$R31 -> 0.059472452 | V31: =-PMT($P31,$Q31,F31)*$AE$1/$R31 -> 0.059472452 | W31: =-PMT($P31,$Q31,G31)*$AE$1/$R31 -> 0.045083955 | X31: =-PMT($P31,$Q31,H31)*$AE$1/$R31 -> 0.030215842 | Y31: =-PMT($P31,$Q31,I31)*$AE$1/$R31 -> 0.030215842 | Z31: =-PMT($P31,$Q31,J31)*$AE$1/$R31 -> 0.020143895 | AA31: =-PMT($P31,$Q31,K31)*$AE$1/$R31 -> 0.020143895 | ... AC31: =-PMT($P31,$Q31,M31)*$AE$1/$R31 -> 0.020143895 | AD31: 1975$/mil lumen-hr | AE31: =A31&B31&C31 -> resid lightingelectricitysolid state
A32: resid clothes washers | B32: electricity | C32: clothes washer | D32: 875 | E32: 875 | F32: 875 | G32: 875 | H32: 900 | I32: 900 | J32: 900 | K32: 900 | L32: 900 | M32: 900 | N32: 2017$/unit | P32: 0.15 | Q32: 10 | R32: 392 | S32: cycles/unit/yr | T32: =-PMT($P32,$Q32,D32)*$AE$1/$R32 -> 0.12301097 | U32: =-PMT($P32,$Q32,E32)*$AE$1/$R32 -> 0.12301097 | V32: =-PMT($P32,$Q32,F32)*$AE$1/$R32 -> 0.12301097 | W32: =-PMT($P32,$Q32,G32)*$AE$1/$R32 -> 0.12301097 | X32: =-PMT($P32,$Q32,H32)*$AE$1/$R32 -> 0.12652557 | Y32: =-PMT($P32,$Q32,I32)*$AE$1/$R32 -> 0.12652557 | Z32: =-PMT($P32,$Q32,J32)*$AE$1/$R32 -> 0.12652557 | AA32: =-PMT($P32,$Q32,K32)*$AE$1/$R32 -> 0.12652557 | ... AC32: =-PMT($P32,$Q32,M32)*$AE$1/$R32 -> 0.12652557 | AD32: 1975$/cycle | AE32: =A32&B32&C32 -> resid clothes washerselectricityclothes washer
A33: resid clothes washers | B33: electricity | C33: clothes washer hi-eff | D33: 875 | E33: 875 | F33: 875 | G33: 875 | H33: 900 | I33: 900 | J33: 900 | K33: 900 | L33: 900 | M33: 900 | N33: 2017$/unit | P33: 0.15 | Q33: 10 | R33: 392 | S33: cycles/unit/yr | T33: =-PMT($P33,$Q33,D33)*$AE$1/$R33 -> 0.12301097 | U33: =-PMT($P33,$Q33,E33)*$AE$1/$R33 -> 0.12301097 | V33: =-PMT($P33,$Q33,F33)*$AE$1/$R33 -> 0.12301097 | W33: =-PMT($P33,$Q33,G33)*$AE$1/$R33 -> 0.12301097 | X33: =-PMT($P33,$Q33,H33)*$AE$1/$R33 -> 0.12652557 | Y33: =-PMT($P33,$Q33,I33)*$AE$1/$R33 -> 0.12652557 | Z33: =-PMT($P33,$Q33,J33)*$AE$1/$R33 -> 0.12652557 | AA33: =-PMT($P33,$Q33,K33)*$AE$1/$R33 -> 0.12652557 | ... AC33: =-PMT($P33,$Q33,M33)*$AE$1/$R33 -> 0.12652557 | AD33: 1975$/cycle | AE33: =A33&B33&C33 -> resid clothes washerselectricityclothes washer hi-eff
A34: resid dishwashers | B34: electricity | C34: dishwasher | D34: 485 | E34: 485 | F34: 485 | G34: 485 | H34: 485 | I34: 485 | J34: 485 | K34: 485 | L34: 485 | M34: 485 | N34: 2017$/unit | P34: 0.15 | Q34: 12.6 | R34: 215 | S34: cycles/unit/yr | T34: =-PMT($P34,$Q34,D34)*$AE$1/$R34 -> 0.11300991 | U34: =-PMT($P34,$Q34,E34)*$AE$1/$R34 -> 0.11300991 | V34: =-PMT($P34,$Q34,F34)*$AE$1/$R34 -> 0.11300991 | W34: =-PMT($P34,$Q34,G34)*$AE$1/$R34 -> 0.11300991 | X34: =-PMT($P34,$Q34,H34)*$AE$1/$R34 -> 0.11300991 | Y34: =-PMT($P34,$Q34,I34)*$AE$1/$R34 -> 0.11300991 | Z34: =-PMT($P34,$Q34,J34)*$AE$1/$R34 -> 0.11300991 | AA34: =-PMT($P34,$Q34,K34)*$AE$1/$R34 -> 0.11300991 | ... AC34: =-PMT($P34,$Q34,M34)*$AE$1/$R34 -> 0.11300991 | AD34: 1975$/cycle | AE34: =A34&B34&C34 -> resid dishwasherselectricitydishwasher
A35: resid dishwashers | B35: electricity | C35: dishwasher hi-eff | D35: 485 | E35: 485 | F35: 485 | G35: 485 | H35: 485 | I35: 485 | J35: 485 | K35: 485 | L35: 485 | M35: 485 | N35: 2017$/unit | P35: 0.15 | Q35: 12.6 | R35: 215 | S35: cycles/unit/yr | T35: =-PMT($P35,$Q35,D35)*$AE$1/$R35 -> 0.11300991 | U35: =-PMT($P35,$Q35,E35)*$AE$1/$R35 -> 0.11300991 | V35: =-PMT($P35,$Q35,F35)*$AE$1/$R35 -> 0.11300991 | W35: =-PMT($P35,$Q35,G35)*$AE$1/$R35 -> 0.11300991 | X35: =-PMT($P35,$Q35,H35)*$AE$1/$R35 -> 0.11300991 | Y35: =-PMT($P35,$Q35,I35)*$AE$1/$R35 -> 0.11300991 | Z35: =-PMT($P35,$Q35,J35)*$AE$1/$R35 -> 0.11300991 | AA35: =-PMT($P35,$Q35,K35)*$AE$1/$R35 -> 0.11300991 | ... AC35: =-PMT($P35,$Q35,M35)*$AE$1/$R35 -> 0.11300991 | AD35: 1975$/cycle | AE35: =A35&B35&C35 -> resid dishwasherselectricitydishwasher hi-eff
A36: resid televisions | B36: electricity | C36: electricity
A37: resid computers | B37: electricity | C37: electricity
A38: resid furnace fans | B38: electricity | C38: electricity
A39: resid other | B39: gas | C39: gas
A40: resid other | B40: electricity | C40: electricity
...

Sheet res_cost
D1: From NEMS | R1: Per-unit info | T1: To GCAM | AE1: 0.2765789 | AF1: conversion from 2017$ to 1975$ | AJ1: 0.2851052 | AK1: conversion from 2015$ to 1975$
A2: Service | B2: Fuel Input | C2: Technology | D2: 2010 | E2: 2015 | F2: 2020 | G2: 2025 | H2: 2030 | I2: 2035 | J2: 2040 | K2: 2045 | L2: 2050 | M2: 2100 | N2: Unit | P2: Discount rate | Q2: Lifetime | R2: Output/yr | S2: Output unit | T2: 2010 | U2: 2015 | V2: 2020 | W2: 2025 | X2: 2030 | Y2: 2035 | Z2: 2040 | AA2: 2045 | AB2: 2050 | AC2: 2100 | AD2: Unit | AE2: lookup | AJ2: 0.2701252 | AK2: conversion from 2018$ to 1975$
A3: resid heating | B3: gas | C3: gas furnace | D3: 2497.494 | E3: 2497.494 | F3: 2497.494 | G3: 2497.494 | H3: 2497.494 | I3: 2497.494 | J3: 2497.494 | K3: 2497.494 | L3: 2497.494 | M3: 2497.494 | N3: 2017$/unit | P3: 0.15 | Q3: 18.4 | R3: 42 | S3: GJ/unit/yr | T3: =-PMT($P3,$Q3,D3)*$AE$1/$R3 -> 2.6710809 | U3: =-PMT($P3,$Q3,E3)*$AE$1/$R3 -> 2.6710809 | V3: =-PMT($P3,$Q3,F3)*$AE$1/$R3 -> 2.6710809 | W3: =-PMT($P3,$Q3,G3)*$AE$1/$R3 -> 2.6710809 | X3: =-PMT($P3,$Q3,H3)*$AE$1/$R3 -> 2.6710809 | Y3: =-PMT($P3,$Q3,I3)*$AE$1/$R3 -> 2.6710809 | Z3: =-PMT($P3,$Q3,J3)*$AE$1/$R3 -> 2.6710809 | AA3: =-PMT($P3,$Q3,K3)*$AE$1/$R3 -> 2.6710809 | ... AC3: =-PMT($P3,$Q3,M3)*$AE$1/$R3 -> 2.6710809 | AD3: 1975$/GJ | AE3: =A3&B3&C3 -> resid heatinggasgas furnace
A4: resid heating | B4: gas | C4: gas furnace hi-eff | D4: 2668 | E4: 2668 | F4: 2668 | G4: 2668 | H4: 2668 | I4: 2668 | J4: 2668 | K4: 2668 | L4: 2668 | M4: 2668 | N4: 2017$/unit | P4: 0.15 | Q4: 18.4 | R4: 42 | S4: GJ/unit/yr | T4: =-PMT($P4,$Q4,D4)*$AE$1/$R4 -> 2.8534378 | U4: =-PMT($P4,$Q4,E4)*$AE$1/$R4 -> 2.8534378 | V4: =-PMT($P4,$Q4,F4)*$AE$1/$R4 -> 2.8534378 | W4: =-PMT($P4,$Q4,G4)*$AE$1/$R4 -> 2.8534378 | X4: =-PMT($P4,$Q4,H4)*$AE$1/$R4 -> 2.8534378 | Y4: =-PMT($P4,$Q4,I4)*$AE$1/$R4 -> 2.8534378 | Z4: =-PMT($P4,$Q4,J4)*$AE$1/$R4 -> 2.8534378 | AA4: =-PMT($P4,$Q4,K4)*$AE$1/$R4 -> 2.8534378 | ... AC4: =-PMT($P4,$Q4,M4)*$AE$1/$R4 -> 2.8534378 | AD4: 1975$/GJ | AE4: =A4&B4&C4 -> resid heatinggasgas furnace hi-eff
A5: resid heating | B5: electricity | C5: electric furnace | D5: 1100 | E5: 1100 | F5: 1100 | G5: 1100 | H5: 1100 | I5: 1100 | J5: 1100 | K5: 1100 | L5: 1100 | M5: 1100 | N5: 2017$/unit | P5: 0.15 | Q5: 18.4 | R5: 42 | S5: GJ/unit/yr | T5: =-PMT($P5,$Q5,D5)*$AE$1/$R5 -> 1.1764549 | U5: =-PMT($P5,$Q5,E5)*$AE$1/$R5 -> 1.1764549 | V5: =-PMT($P5,$Q5,F5)*$AE$1/$R5 -> 1.1764549 | W5: =-PMT($P5,$Q5,G5)*$AE$1/$R5 -> 1.1764549 | X5: =-PMT($P5,$Q5,H5)*$AE$1/$R5 -> 1.1764549 | Y5: =-PMT($P5,$Q5,I5)*$AE$1/$R5 -> 1.1764549 | Z5: =-PMT($P5,$Q5,J5)*$AE$1/$R5 -> 1.1764549 | AA5: =-PMT($P5,$Q5,K5)*$AE$1/$R5 -> 1.1764549 | ... AC5: =-PMT($P5,$Q5,M5)*$AE$1/$R5 -> 1.1764549 | AD5: 1975$/GJ | AE5: =A5&B5&C5 -> resid heatingelectricityelectric furnace
A6: resid heating | B6: electricity | C6: electric heat pump | D6: 6100 | E6: 6100 | F6: 6100 | G6: 6100 | H6: 6100 | I6: 6100 | J6: 6100 | K6: 6100 | L6: 6100 | M6: 6100 | N6: 2017$/unit | P6: 0.15 | Q6: 18.4 | R6: 42 | S6: GJ/unit/yr | T6: =-PMT($P6,$Q6,D6)*$AE$1/$R6 -> 6.5239769 | U6: =-PMT($P6,$Q6,E6)*$AE$1/$R6 -> 6.5239769 | V6: =-PMT($P6,$Q6,F6)*$AE$1/$R6 -> 6.5239769 | W6: =-PMT($P6,$Q6,G6)*$AE$1/$R6 -> 6.5239769 | X6: =-PMT($P6,$Q6,H6)*$AE$1/$R6 -> 6.5239769 | Y6: =-PMT($P6,$Q6,I6)*$AE$1/$R6 -> 6.5239769 | Z6: =-PMT($P6,$Q6,J6)*$AE$1/$R6 -> 6.5239769 | AA6: =-PMT($P6,$Q6,K6)*$AE$1/$R6 -> 6.5239769 | ... AC6: =-PMT($P6,$Q6,M6)*$AE$1/$R6 -> 6.5239769 | AD6: 1975$/GJ | AE6: =A6&B6&C6 -> resid heatingelectricityelectric heat pump
A7: resid heating | B7: refined liquids | C7: fuel furnace | D7: 4225 | E7: 4225 | F7: 4225 | G7: 4225 | H7: 4225 | I7: 4225 | J7: 4225 | K7: 4225 | L7: 4225 | M7: 4225 | N7: 2017$/unit | P7: 0.15 | Q7: 18.4 | R7: 42 | S7: GJ/unit/yr | T7: =-PMT($P7,$Q7,D7)*$AE$1/$R7 -> 4.5186561 | U7: =-PMT($P7,$Q7,E7)*$AE$1/$R7 -> 4.5186561 | V7: =-PMT($P7,$Q7,F7)*$AE$1/$R7 -> 4.5186561 | W7: =-PMT($P7,$Q7,G7)*$AE$1/$R7 -> 4.5186561 | X7: =-PMT($P7,$Q7,H7)*$AE$1/$R7 -> 4.5186561 | Y7: =-PMT($P7,$Q7,I7)*$AE$1/$R7 -> 4.5186561 | Z7: =-PMT($P7,$Q7,J7)*$AE$1/$R7 -> 4.5186561 | AA7: =-PMT($P7,$Q7,K7)*$AE$1/$R7 -> 4.5186561 | ... AC7: =-PMT($P7,$Q7,M7)*$AE$1/$R7 -> 4.5186561 | AD7: 1975$/GJ | AE7: =A7&B7&C7 -> resid heatingrefined liquidsfuel furnace
A8: resid heating | B8: refined liquids | C8: fuel furnace hi-eff | D8: 4350 | E8: 4350 | F8: 4350 | G8: 4350 | H8: 4350 | I8: 4350 | J8: 4350 | K8: 4350 | L8: 4350 | M8: 4350 | N8: 2017$/unit | P8: 0.15 | Q8: 18.4 | R8: 42 | S8: GJ/unit/yr | T8: =-PMT($P8,$Q8,D8)*$AE$1/$R8 -> 4.6523442 | U8: =-PMT($P8,$Q8,E8)*$AE$1/$R8 -> 4.6523442 | V8: =-PMT($P8,$Q8,F8)*$AE$1/$R8 -> 4.6523442 | W8: =-PMT($P8,$Q8,G8)*$AE$1/$R8 -> 4.6523442 | X8: =-PMT($P8,$Q8,H8)*$AE$1/$R8 -> 4.6523442 | Y8: =-PMT($P8,$Q8,I8)*$AE$1/$R8 -> 4.6523442 | Z8: =-PMT($P8,$Q8,J8)*$AE$1/$R8 -> 4.6523442 | AA8: =-PMT($P8,$Q8,K8)*$AE$1/$R8 -> 4.6523442 | ... AC8: =-PMT($P8,$Q8,M8)*$AE$1/$R8 -> 4.6523442 | AD8: 1975$/GJ | AE8: =A8&B8&C8 -> resid heatingrefined liquidsfuel furnace hi-eff
A9: resid cooling | B9: electricity | C9: air conditioning | D9: 3680.2768 | E9: 3680.2768 | F9: 3680.2768 | G9: 3942.2146 | H9: 3942.2146 | I9: 3942.2146 | J9: 3942.2146 | K9: 3942.2146 | L9: 3942.2146 | M9: 3942.2146 | N9: 2017$/unit | P9: 0.15 | Q9: 18.4 | R9: 19 | S9: GJ/unit/yr | T9: =-PMT($P9,$Q9,D9)*$AE$1/$R9 -> 8.7007914 | U9: =-PMT($P9,$Q9,E9)*$AE$1/$R9 -> 8.7007914 | V9: =-PMT($P9,$Q9,F9)*$AE$1/$R9 -> 8.7007914 | W9: =-PMT($P9,$Q9,G9)*$AE$1/$R9 -> 9.3200562 | X9: =-PMT($P9,$Q9,H9)*$AE$1/$R9 -> 9.3200562 | Y9: =-PMT($P9,$Q9,I9)*$AE$1/$R9 -> 9.3200562 | Z9: =-PMT($P9,$Q9,J9)*$AE$1/$R9 -> 9.3200562 | AA9: =-PMT($P9,$Q9,K9)*$AE$1/$R9 -> 9.3200562 | ... AC9: =-PMT($P9,$Q9,M9)*$AE$1/$R9 -> 9.3200562 | AD9: 1975$/GJ | AE9: =A9&B9&C9 -> resid coolingelectricityair conditioning
A10: resid cooling | B10: electricity | C10: air conditioning hi-eff | D10: 6100 | E10: 6100 | F10: 6100 | G10: 6361.9378 | H10: 6361.9378 | I10: 6361.9378 | J10: 6361.9378 | K10: 6361.9378 | L10: 6361.9378 | M10: 6361.9378 | N10: 2017$/unit | P10: 0.15 | Q10: 18.4 | R10: 19 | S10: GJ/unit/yr | T10: =-PMT($P10,$Q10,D10)*$AE$1/$R10 -> 14.421423 | U10: =-PMT($P10,$Q10,E10)*$AE$1/$R10 -> 14.421423 | V10: =-PMT($P10,$Q10,F10)*$AE$1/$R10 -> 14.421423 | W10: =-PMT($P10,$Q10,G10)*$AE$1/$R10 -> 15.040687 | X10: =-PMT($P10,$Q10,H10)*$AE$1/$R10 -> 15.040687 | Y10: =-PMT($P10,$Q10,I10)*$AE$1/$R10 -> 15.040687 | Z10: =-PMT($P10,$Q10,J10)*$AE$1/$R10 -> 15.040687 | AA10: =-PMT($P10,$Q10,K10)*$AE$1/$R10 -> 15.040687 | ... AC10: =-PMT($P10,$Q10,M10)*$AE$1/$R10 -> 15.040687 | AD10: 1975$/GJ | AE10: =A10&B10&C10 -> resid coolingelectricityair conditioning hi-eff
A11: resid hot water | B11: gas | C11: gas water heater | D11: 1925 | E11: 1925 | F11: 1925 | G11: 1925 | H11: 1925 | I11: 1925 | J11: 1925 | K11: 1925 | L11: 1925 | M11: 1925 | N11: 2017$/unit | P11: 0.25 | Q11: 9 | R11: 9 | S11: GJ/unit/yr | T11: =-PMT($P11,$Q11,D11)*$AE$1/$R11 -> 17.081995 | U11: =-PMT($P11,$Q11,E11)*$AE$1/$R11 -> 17.081995 | V11: =-PMT($P11,$Q11,F11)*$AE$1/$R11 -> 17.081995 | W11: =-PMT($P11,$Q11,G11)*$AE$1/$R11 -> 17.081995 | X11: =-PMT($P11,$Q11,H11)*$AE$1/$R11 -> 17.081995 | Y11: =-PMT($P11,$Q11,I11)*$AE$1/$R11 -> 17.081995 | Z11: =-PMT($P11,$Q11,J11)*$AE$1/$R11 -> 17.081995 | AA11: =-PMT($P11,$Q11,K11)*$AE$1/$R11 -> 17.081995 | ... AC11: =-PMT($P11,$Q11,M11)*$AE$1/$R11 -> 17.081995 | AD11: 1975$/GJ | AE11: =A11&B11&C11 -> resid hot watergasgas water heater
A12: resid hot water | B12: gas | C12: gas water heater hi-eff | D12: 2025 | E12: 2025 | F12: 2025 | G12: 2025 | H12: 2025 | I12: 2025 | J12: 2025 | K12: 2025 | L12: 2025 | M12: 2025 | N12: 2017$/unit | P12: 0.25 | Q12: 9 | R12: 9 | S12: GJ/unit/yr | T12: =-PMT($P12,$Q12,D12)*$AE$1/$R12 -> 17.969371 | U12: =-PMT($P12,$Q12,E12)*$AE$1/$R12 -> 17.969371 | V12: =-PMT($P12,$Q12,F12)*$AE$1/$R12 -> 17.969371 | W12: =-PMT($P12,$Q12,G12)*$AE$1/$R12 -> 17.969371 | X12: =-PMT($P12,$Q12,H12)*$AE$1/$R12 -> 17.969371 | Y12: =-PMT($P12,$Q12,I12)*$AE$1/$R12 -> 17.969371 | Z12: =-PMT($P12,$Q12,J12)*$AE$1/$R12 -> 17.969371 | AA12: =-PMT($P12,$Q12,K12)*$AE$1/$R12 -> 17.969371 | ... AC12: =-PMT($P12,$Q12,M12)*$AE$1/$R12 -> 17.969371 | AD12: 1975$/GJ | AE12: =A12&B12&C12 -> resid hot watergasgas water heater hi-eff
A13: resid hot water | B13: electricity | C13: electric heat pump water heater | D13: 2075 | E13: 2075 | F13: 2075 | G13: 2075 | H13: 2075 | I13: 2075 | J13: 2075 | K13: 2075 | L13: 2075 | M13: 2075 | N13: 2017$/unit | P13: 0.25 | Q13: 14 | R13: 9 | S13: GJ/unit/yr | T13: =-PMT($P13,$Q13,D13)*$AE$1/$R13 -> 16.675078 | U13: =-PMT($P13,$Q13,E13)*$AE$1/$R13 -> 16.675078 | V13: =-PMT($P13,$Q13,F13)*$AE$1/$R13 -> 16.675078 | W13: =-PMT($P13,$Q13,G13)*$AE$1/$R13 -> 16.675078 | X13: =-PMT($P13,$Q13,H13)*$AE$1/$R13 -> 16.675078 | Y13: =-PMT($P13,$Q13,I13)*$AE$1/$R13 -> 16.675078 | Z13: =-PMT($P13,$Q13,J13)*$AE$1/$R13 -> 16.675078 | AA13: =-PMT($P13,$Q13,K13)*$AE$1/$R13 -> 16.675078 | ... AC13: =-PMT($P13,$Q13,M13)*$AE$1/$R13 -> 16.675078 | AD13: 1975$/GJ | AE13: =A13&B13&C13 -> resid hot waterelectricityelectric heat pump water heater
A14: resid hot water | B14: electricity | C14: electric resistance water heater | D14: 850 | E14: 850 | F14: 850 | G14: 850 | H14: 850 | I14: 850 | J14: 850 | K14: 850 | L14: 850 | M14: 850 | N14: 2017$/unit | P14: 0.25 | Q14: 14 | R14: 9 | S14: GJ/unit/yr | T14: =-PMT($P14,$Q14,D14)*$AE$1/$R14 -> 6.8307549 | U14: =-PMT($P14,$Q14,E14)*$AE$1/$R14 -> 6.8307549 | V14: =-PMT($P14,$Q14,F14)*$AE$1/$R14 -> 6.8307549 | W14: =-PMT($P14,$Q14,G14)*$AE$1/$R14 -> 6.8307549 | X14: =-PMT($P14,$Q14,H14)*$AE$1/$R14 -> 6.8307549 | Y14: =-PMT($P14,$Q14,I14)*$AE$1/$R14 -> 6.8307549 | Z14: =-PMT($P14,$Q14,J14)*$AE$1/$R14 -> 6.8307549 | AA14: =-PMT($P14,$Q14,K14)*$AE$1/$R14 -> 6.8307549 | ... AC14: =-PMT($P14,$Q14,M14)*$AE$1/$R14 -> 6.8307549 | AD14: 1975$/GJ | AE14: =A14&B14&C14 -> resid hot waterelectricityelectric resistance water heater
... A17: resid hot water | B17: refined liquids | C17: fuel water heater hi-eff | D17: 1925 | E17: 1925 | F17: 1925 | G17: 1925 | H17: 1925 | I17: 1925 | J17: 1925 | K17: 1925 | L17: 1925 | M17: 1925 | N17: 2017$/unit | P17: 0.25 | Q17: 9 | R17: 9 | S17: GJ/unit/yr | T17: =-PMT($P17,$Q17,D17)*$AE$1/$R17 -> 17.081995 | U17: =-PMT($P17,$Q17,E17)*$AE$1/$R17 -> 17.081995 | V17: =-PMT($P17,$Q17,F17)*$AE$1/$R17 -> 17.081995 | W17: =-PMT($P17,$Q17,G17)*$AE$1/$R17 -> 17.081995 | X17: =-PMT($P17,$Q17,H17)*$AE$1/$R17 -> 17.081995 | Y17: =-PMT($P17,$Q17,I17)*$AE$1/$R17 -> 17.081995 | Z17: =-PMT($P17,$Q17,J17)*$AE$1/$R17 -> 17.081995 | AA17: =-PMT($P17,$Q17,K17)*$AE$1/$R17 -> 17.081995 | ... AC17: =-PMT($P17,$Q17,M17)*$AE$1/$R17 -> 17.081995 | AD17: 1975$/GJ | AE17: =A17&B17&C17 -> resid hot waterrefined liquidsfuel water heater hi-eff
A18: resid refrigerators | B18: electricity | C18: refrigerator | D18: 1096.6667 | E18: 1096.6667 | F18: 1096.6667 | G18: 1096.6667 | H18: 1096.6667 | I18: 1096.6667 | J18: 1096.6667 | K18: 1096.6667 | L18: 1096.6667 | M18: 1096.6667 | N18: 2017$/unit | P18: 0.15 | Q18: 19 | R18: =res_eff!D18*res_eff!P18*0.0036 -> 3.696 | S18: GJ/unit/yr | T18: =-PMT($P18,$Q18,D18)*$AE$1/$R18 -> 13.240182 | U18: =-PMT($P18,$Q18,E18)*$AE$1/$R18 -> 13.240182 | V18: =-PMT($P18,$Q18,F18)*$AE$1/$R18 -> 13.240182 | W18: =-PMT($P18,$Q18,G18)*$AE$1/$R18 -> 13.240182 | X18: =-PMT($P18,$Q18,H18)*$AE$1/$R18 -> 13.240182 | Y18: =-PMT($P18,$Q18,I18)*$AE$1/$R18 -> 13.240182 | Z18: =-PMT($P18,$Q18,J18)*$AE$1/$R18 -> 13.240182 | AA18: =-PMT($P18,$Q18,K18)*$AE$1/$R18 -> 13.240182 | ... AC18: =-PMT($P18,$Q18,M18)*$AE$1/$R18 -> 13.240182 | AD18: 1975$/GJ | AE18: =A18&B18&C18 -> resid refrigeratorselectricityrefrigerator
A19: resid refrigerators | B19: electricity | C19: refrigerator hi-eff | D19: 1186.67 | E19: 1186.67 | F19: 1186.67 | G19: 1186.67 | H19: 1186.67 | I19: 1186.67 | J19: 1186.67 | K19: 1186.67 | L19: 1186.67 | M19: 1186.67 | N19: 2017$/unit | P19: 0.15 | Q19: 19 | R19: =R18 -> 3.696 | S19: GJ/unit/yr | T19: =-PMT($P19,$Q19,D19)*$AE$1/$R19 -> 14.326803 | U19: =-PMT($P19,$Q19,E19)*$AE$1/$R19 -> 14.326803 | V19: =-PMT($P19,$Q19,F19)*$AE$1/$R19 -> 14.326803 | W19: =-PMT($P19,$Q19,G19)*$AE$1/$R19 -> 14.326803 | X19: =-PMT($P19,$Q19,H19)*$AE$1/$R19 -> 14.326803 | Y19: =-PMT($P19,$Q19,I19)*$AE$1/$R19 -> 14.326803 | Z19: =-PMT($P19,$Q19,J19)*$AE$1/$R19 -> 14.326803 | AA19: =-PMT($P19,$Q19,K19)*$AE$1/$R19 -> 14.326803 | ... AC19: =-PMT($P19,$Q19,M19)*$AE$1/$R19 -> 14.326803 | AD19: 1975$/GJ | AE19: =A19&B19&C19 -> resid refrigeratorselectricityrefrigerator hi-eff
A20: resid cooking | B20: gas | C20: gas oven | D20: 370 | E20: 370 | F20: 370 | G20: 370 | H20: 370 | I20: 370 | J20: 370 | K20: 370 | L20: 370 | M20: 370 | N20: 2017$/unit | P20: 0.15 | Q20: 19 | R20: =$R$22 -> 0.79765211 | S20: GJ/unit/yr | T20: =-PMT($P20,$Q20,D20)*$AE$1/$R20 -> 20.698529 | U20: =-PMT($P20,$Q20,E20)*$AE$1/$R20 -> 20.698529 | V20: =-PMT($P20,$Q20,F20)*$AE$1/$R20 -> 20.698529 | W20: =-PMT($P20,$Q20,G20)*$AE$1/$R20 -> 20.698529 | X20: =-PMT($P20,$Q20,H20)*$AE$1/$R20 -> 20.698529 | Y20: =-PMT($P20,$Q20,I20)*$AE$1/$R20 -> 20.698529 | Z20: =-PMT($P20,$Q20,J20)*$AE$1/$R20 -> 20.698529 | AA20: =-PMT($P20,$Q20,K20)*$AE$1/$R20 -> 20.698529 | ... AC20: =-PMT($P20,$Q20,M20)*$AE$1/$R20 -> 20.698529 | AD20: 1975$/GJ | AE20: =A20&B20&C20 -> resid cookinggasgas oven
A21: resid cooking | B21: gas | C21: gas oven hi-eff | D21: 370 | E21: 370 | F21: 370 | G21: 370 | H21: 370 | I21: 370 | J21: 370 | K21: 370 | L21: 370 | M21: 370 | N21: 2017$/unit | P21: 0.15 | Q21: 19 | R21: =$R$22 -> 0.79765211 | S21: GJ/unit/yr | T21: =-PMT($P21,$Q21,D21)*$AE$1/$R21 -> 20.698529 | U21: =-PMT($P21,$Q21,E21)*$AE$1/$R21 -> 20.698529 | V21: =-PMT($P21,$Q21,F21)*$AE$1/$R21 -> 20.698529 | W21: =-PMT($P21,$Q21,G21)*$AE$1/$R21 -> 20.698529 | X21: =-PMT($P21,$Q21,H21)*$AE$1/$R21 -> 20.698529 | Y21: =-PMT($P21,$Q21,I21)*$AE$1/$R21 -> 20.698529 | Z21: =-PMT($P21,$Q21,J21)*$AE$1/$R21 -> 20.698529 | AA21: =-PMT($P21,$Q21,K21)*$AE$1/$R21 -> 20.698529 | ... AC21: =-PMT($P21,$Q21,M21)*$AE$1/$R21 -> 20.698529 | AD21: 1975$/GJ | AE21: =A21&B21&C21 -> resid cookinggasgas oven hi-eff
A22: resid cooking | B22: electricity | C22: electric oven | D22: 770 | E22: 770 | F22: 770 | G22: 770 | H22: 770 | I22: 770 | J22: 770 | K22: 770 | L22: 770 | M22: 770 | N22: 2017$/unit | P22: 0.15 | Q22: 19 | R22: =res_eff!D22*res_eff!P22*0.0036 -> 0.79765211 | S22: GJ/unit/yr | T22: =-PMT($P22,$Q22,D22)*$AE$1/$R22 -> 43.075317 | U22: =-PMT($P22,$Q22,E22)*$AE$1/$R22 -> 43.075317 | V22: =-PMT($P22,$Q22,F22)*$AE$1/$R22 -> 43.075317 | W22: =-PMT($P22,$Q22,G22)*$AE$1/$R22 -> 43.075317 | X22: =-PMT($P22,$Q22,H22)*$AE$1/$R22 -> 43.075317 | Y22: =-PMT($P22,$Q22,I22)*$AE$1/$R22 -> 43.075317 | Z22: =-PMT($P22,$Q22,J22)*$AE$1/$R22 -> 43.075317 | AA22: =-PMT($P22,$Q22,K22)*$AE$1/$R22 -> 43.075317 | ... AC22: =-PMT($P22,$Q22,M22)*$AE$1/$R22 -> 43.075317 | AD22: 1975$/GJ | AE22: =A22&B22&C22 -> resid cookingelectricityelectric oven
A23: resid clothes dryers | B23: gas | C23: clothes dryer | D23: 660 | E23: 660 | F23: 660 | G23: 660 | H23: 660 | I23: 660 | J23: 660 | K23: 660 | L23: 660 | M23: 660 | N23: 2017$/unit | P23: 0.15 | Q23: 10 | R23: =res_eff!D25*res_eff!P25*0.454 -> 1018.776 | S23: kg/unit/yr | T23: =-PMT($P23,$Q23,D23)*$AE$1/$R23 -> 0.035701552 | U23: =-PMT($P23,$Q23,E23)*$AE$1/$R23 -> 0.035701552 | V23: =-PMT($P23,$Q23,F23)*$AE$1/$R23 -> 0.035701552 | W23: =-PMT($P23,$Q23,G23)*$AE$1/$R23 -> 0.035701552 | X23: =-PMT($P23,$Q23,H23)*$AE$1/$R23 -> 0.035701552 | Y23: =-PMT($P23,$Q23,I23)*$AE$1/$R23 -> 0.035701552 | Z23: =-PMT($P23,$Q23,J23)*$AE$1/$R23 -> 0.035701552 | AA23: =-PMT($P23,$Q23,K23)*$AE$1/$R23 -> 0.035701552 | ... AC23: =-PMT($P23,$Q23,M23)*$AE$1/$R23 -> 0.035701552 | AD23: 1975$/kg | AE23: =A23&B23&C23 -> resid clothes dryersgasclothes dryer
A24: resid clothes dryers | B24: gas | C24: clothes dryer | D24: 660 | E24: 660 | F24: 660 | G24: 660 | H24: 660 | I24: 660 | J24: 660 | K24: 660 | L24: 660 | M24: 660 | N24: 2017$/unit | P24: 0.15 | Q24: 10 | R24: =$R$23 -> 1018.776 | S24: kg/unit/yr | T24: =-PMT($P24,$Q24,D24)*$AE$1/$R24 -> 0.035701552 | U24: =-PMT($P24,$Q24,E24)*$AE$1/$R24 -> 0.035701552 | V24: =-PMT($P24,$Q24,F24)*$AE$1/$R24 -> 0.035701552 | W24: =-PMT($P24,$Q24,G24)*$AE$1/$R24 -> 0.035701552 | X24: =-PMT($P24,$Q24,H24)*$AE$1/$R24 -> 0.035701552 | Y24: =-PMT($P24,$Q24,I24)*$AE$1/$R24 -> 0.035701552 | Z24: =-PMT($P24,$Q24,J24)*$AE$1/$R24 -> 0.035701552 | AA24: =-PMT($P24,$Q24,K24)*$AE$1/$R24 -> 0.035701552 | ... AC24: =-PMT($P24,$Q24,M24)*$AE$1/$R24 -> 0.035701552 | AD24: 1975$/kg | AE24: =A24&B24&C24 -> resid clothes dryersgasclothes dryer
A25: resid clothes dryers | B25: electricity | C25: clothes dryer | D25: 540 | E25: 540 | F25: 540 | G25: 540 | H25: 540 | I25: 540 | J25: 540 | K25: 540 | L25: 540 | M25: 540 | N25: 2017$/unit | P25: 0.15 | Q25: 10 | R25: =$R$23 -> 1018.776 | S25: kg/unit/yr | T25: =-PMT($P25,$Q25,D25)*$AE$1/$R25 -> 0.029210361 | U25: =-PMT($P25,$Q25,E25)*$AE$1/$R25 -> 0.029210361 | V25: =-PMT($P25,$Q25,F25)*$AE$1/$R25 -> 0.029210361 | W25: =-PMT($P25,$Q25,G25)*$AE$1/$R25 -> 0.029210361 | X25: =-PMT($P25,$Q25,H25)*$AE$1/$R25 -> 0.029210361 | Y25: =-PMT($P25,$Q25,I25)*$AE$1/$R25 -> 0.029210361 | Z25: =-PMT($P25,$Q25,J25)*$AE$1/$R25 -> 0.029210361 | AA25: =-PMT($P25,$Q25,K25)*$AE$1/$R25 -> 0.029210361 | ... AC25: =-PMT($P25,$Q25,M25)*$AE$1/$R25 -> 0.029210361 | AD25: 1975$/kg | AE25: =A25&B25&C25 -> resid clothes dryerselectricityclothes dryer
A26: resid clothes dryers | B26: electricity | C26: clothes dryer hi-eff | D26: 655 | E26: 655 | F26: 655 | G26: 655 | H26: 655 | I26: 655 | J26: 655 | K26: 655 | L26: 655 | M26: 655 | N26: 2017$/unit | P26: 0.15 | Q26: 10 | R26: =$R$23 -> 1018.776 | S26: kg/unit/yr | T26: =-PMT($P26,$Q26,D26)*$AE$1/$R26 -> 0.035431086 | U26: =-PMT($P26,$Q26,E26)*$AE$1/$R26 -> 0.035431086 | V26: =-PMT($P26,$Q26,F26)*$AE$1/$R26 -> 0.035431086 | W26: =-PMT($P26,$Q26,G26)*$AE$1/$R26 -> 0.035431086 | X26: =-PMT($P26,$Q26,H26)*$AE$1/$R26 -> 0.035431086 | Y26: =-PMT($P26,$Q26,I26)*$AE$1/$R26 -> 0.035431086 | Z26: =-PMT($P26,$Q26,J26)*$AE$1/$R26 -> 0.035431086 | AA26: =-PMT($P26,$Q26,K26)*$AE$1/$R26 -> 0.035431086 | ... AC26: =-PMT($P26,$Q26,M26)*$AE$1/$R26 -> 0.035431086 | AD26: 1975$/kg | AE26: =A26&B26&C26 -> resid clothes dryerselectricityclothes dryer hi-eff
A27: resid freezers | B27: electricity | C27: freezer | D27: 625 | E27: 625 | F27: 625 | G27: 625 | H27: 625 | I27: 625 | J27: 625 | K27: 625 | L27: 625 | M27: 625 | N27: 2017$/unit | P27: 0.15 | Q27: 10 | R27: =res_eff!D27*res_eff!P27*0.0036 -> 1.3374 | S27: GJ/unit/yr | T27: =-PMT($P27,$Q27,D27)*$AE$1/$R27 -> 25.753756 | U27: =-PMT($P27,$Q27,E27)*$AE$1/$R27 -> 25.753756 | V27: =-PMT($P27,$Q27,F27)*$AE$1/$R27 -> 25.753756 | W27: =-PMT($P27,$Q27,G27)*$AE$1/$R27 -> 25.753756 | X27: =-PMT($P27,$Q27,H27)*$AE$1/$R27 -> 25.753756 | Y27: =-PMT($P27,$Q27,I27)*$AE$1/$R27 -> 25.753756 | Z27: =-PMT($P27,$Q27,J27)*$AE$1/$R27 -> 25.753756 | AA27: =-PMT($P27,$Q27,K27)*$AE$1/$R27 -> 25.753756 | ... AC27: =-PMT($P27,$Q27,M27)*$AE$1/$R27 -> 25.753756 | AD27: 1975$/GJ | AE27: =A27&B27&C27 -> resid freezerselectricityfreezer
A28: resid freezers | B28: electricity | C28: freezer hi-eff | D28: 625 | E28: 625 | F28: 625 | G28: 625 | H28: 625 | I28: 625 | J28: 625 | K28: 625 | L28: 625 | M28: 625 | N28: 2017$/unit | P28: 0.15 | Q28: 10 | R28: =R27 -> 1.3374 | S28: GJ/unit/yr | T28: =-PMT($P28,$Q28,D28)*$AE$1/$R28 -> 25.753756 | U28: =-PMT($P28,$Q28,E28)*$AE$1/$R28 -> 25.753756 | V28: =-PMT($P28,$Q28,F28)*$AE$1/$R28 -> 25.753756 | W28: =-PMT($P28,$Q28,G28)*$AE$1/$R28 -> 25.753756 | X28: =-PMT($P28,$Q28,H28)*$AE$1/$R28 -> 25.753756 | Y28: =-PMT($P28,$Q28,I28)*$AE$1/$R28 -> 25.753756 | Z28: =-PMT($P28,$Q28,J28)*$AE$1/$R28 -> 25.753756 | AA28: =-PMT($P28,$Q28,K28)*$AE$1/$R28 -> 25.753756 | ... AC28: =-PMT($P28,$Q28,M28)*$AE$1/$R28 -> 25.753756 | AD28: 1975$/GJ | AE28: =A28&B28&C28 -> resid freezerselectricityfreezer hi-eff
A29: resid lighting | B29: electricity | C29: incandescent | D29: 1.99 | E29: 1.99 | F29: 1.99 | G29: 1.99 | H29: 1.99 | I29: 1.99 | J29: 1.99 | K29: 1.99 | L29: 1.99 | M29: 1.99 | N29: 2017$/unit | P29: 0.15 | Q29: =[1]rsmlgt_AT15!$G$38/8760/0.1 -> 1.1415525 | R29: =[1]rsmlgt_AT15!$F$36*res_eff!D29*8760*0.1/1000000 -> 0.8688168 | S29: mil lumen-hours/unit/yr | T29: =-PMT($P29,$Q29,D29)*$AE$1/$R29 -> 0.64436911 | U29: =-PMT($P29,$Q29,E29)*$AE$1/$R29 -> 0.64436911 | V29: =-PMT($P29,$Q29,F29)*$AE$1/$R29 -> 0.64436911 | W29: =-PMT($P29,$Q29,G29)*$AE$1/$R29 -> 0.64436911 | X29: =-PMT($P29,$Q29,H29)*$AE$1/$R29 -> 0.64436911 | Y29: =-PMT($P29,$Q29,I29)*$AE$1/$R29 -> 0.64436911 | Z29: =-PMT($P29,$Q29,J29)*$AE$1/$R29 -> 0.64436911 | AA29: =-PMT($P29,$Q29,K29)*$AE$1/$R29 -> 0.64436911 | ... AC29: =-PMT($P29,$Q29,M29)*$AE$1/$R29 -> 0.64436911 | AD29: 1975$/mil lumen-hr | AE29: =A29&B29&C29 -> resid lightingelectricityincandescent
A30: resid lighting | B30: electricity | C30: fluorescent | D30: 1.98 | E30: 1.98 | F30: 1.98 | G30: 1.98 | H30: 1.89 | I30: 1.89 | J30: 1.79 | K30: 1.79 | L30: 1.79 | M30: 1.79 | N30: 2017$/unit | P30: 0.15 | Q30: =[1]rsmlgt_AT15!$G$41/8760/0.1 -> 11.415525 | R30: =$R$29 -> 0.8688168 | S30: mil lumen-hours/unit/yr | T30: =-PMT($P30,$Q30,D30)*$AE$1/$R30 -> 0.1186011 | U30: =-PMT($P30,$Q30,E30)*$AE$1/$R30 -> 0.1186011 | V30: =-PMT($P30,$Q30,F30)*$AE$1/$R30 -> 0.1186011 | W30: =-PMT($P30,$Q30,G30)*$AE$1/$R30 -> 0.1186011 | X30: =-PMT($P30,$Q30,H30)*$AE$1/$R30 -> 0.11321014 | Y30: =-PMT($P30,$Q30,I30)*$AE$1/$R30 -> 0.11321014 | Z30: =-PMT($P30,$Q30,J30)*$AE$1/$R30 -> 0.10722019 | AA30: =-PMT($P30,$Q30,K30)*$AE$1/$R30 -> 0.10722019 | ... AC30: =-PMT($P30,$Q30,M30)*$AE$1/$R30 -> 0.10722019 | AD30: 1975$/mil lumen-hr | AE30: =A30&B30&C30 -> resid lightingelectricityfluorescent
A31: resid lighting | B31: electricity | C31: solid state | D31: 1.24 | E31: 1.24 | F31: 1.24 | G31: 0.94 | H31: 0.63 | I31: 0.63 | J31: 0.42 | K31: 0.42 | L31: 0.42 | M31: 0.42 | N31: 2017$/unit | P31: 0.15 | Q31: =[1]rsmlgt_AT15!$G$50/8760/0.1 -> 38.835616 | R31: =$R$29 -> 0.8688168 | S31: mil lumen-hours/unit/yr | T31: =-PMT($P31,$Q31,D31)*$AE$1/$R31 -> 0.059472452 | U31: =-PMT($P31,$Q31,E31)*$AE$1/$R31 -> 0.059472452 | V31: =-PMT($P31,$Q31,F31)*$AE$1/$R31 -> 0.059472452 | W31: =-PMT($P31,$Q31,G31)*$AE$1/$R31 -> 0.045083955 | X31: =-PMT($P31,$Q31,H31)*$AE$1/$R31 -> 0.030215842 | Y31: =-PMT($P31,$Q31,I31)*$AE$1/$R31 -> 0.030215842 | Z31: =-PMT($P31,$Q31,J31)*$AE$1/$R31 -> 0.020143895 | AA31: =-PMT($P31,$Q31,K31)*$AE$1/$R31 -> 0.020143895 | ... AC31: =-PMT($P31,$Q31,M31)*$AE$1/$R31 -> 0.020143895 | AD31: 1975$/mil lumen-hr | AE31: =A31&B31&C31 -> resid lightingelectricitysolid state
A32: resid clothes washers | B32: electricity | C32: clothes washer | D32: 875 | E32: 875 | F32: 875 | G32: 875 | H32: 900 | I32: 900 | J32: 900 | K32: 900 | L32: 900 | M32: 900 | N32: 2017$/unit | P32: 0.15 | Q32: 10 | R32: 392 | S32: cycles/unit/yr | T32: =-PMT($P32,$Q32,D32)*$AE$1/$R32 -> 0.12301097 | U32: =-PMT($P32,$Q32,E32)*$AE$1/$R32 -> 0.12301097 | V32: =-PMT($P32,$Q32,F32)*$AE$1/$R32 -> 0.12301097 | W32: =-PMT($P32,$Q32,G32)*$AE$1/$R32 -> 0.12301097 | X32: =-PMT($P32,$Q32,H32)*$AE$1/$R32 -> 0.12652557 | Y32: =-PMT($P32,$Q32,I32)*$AE$1/$R32 -> 0.12652557 | Z32: =-PMT($P32,$Q32,J32)*$AE$1/$R32 -> 0.12652557 | AA32: =-PMT($P32,$Q32,K32)*$AE$1/$R32 -> 0.12652557 | ... AC32: =-PMT($P32,$Q32,M32)*$AE$1/$R32 -> 0.12652557 | AD32: 1975$/cycle | AE32: =A32&B32&C32 -> resid clothes washerselectricityclothes washer
A33: resid clothes washers | B33: electricity | C33: clothes washer hi-eff | D33: 875 | E33: 875 | F33: 875 | G33: 875 | H33: 900 | I33: 900 | J33: 900 | K33: 900 | L33: 900 | M33: 900 | N33: 2017$/unit | P33: 0.15 | Q33: 10 | R33: 392 | S33: cycles/unit/yr | T33: =-PMT($P33,$Q33,D33)*$AE$1/$R33 -> 0.12301097 | U33: =-PMT($P33,$Q33,E33)*$AE$1/$R33 -> 0.12301097 | V33: =-PMT($P33,$Q33,F33)*$AE$1/$R33 -> 0.12301097 | W33: =-PMT($P33,$Q33,G33)*$AE$1/$R33 -> 0.12301097 | X33: =-PMT($P33,$Q33,H33)*$AE$1/$R33 -> 0.12652557 | Y33: =-PMT($P33,$Q33,I33)*$AE$1/$R33 -> 0.12652557 | Z33: =-PMT($P33,$Q33,J33)*$AE$1/$R33 -> 0.12652557 | AA33: =-PMT($P33,$Q33,K33)*$AE$1/$R33 -> 0.12652557 | ... AC33: =-PMT($P33,$Q33,M33)*$AE$1/$R33 -> 0.12652557 | AD33: 1975$/cycle | AE33: =A33&B33&C33 -> resid clothes washerselectricityclothes washer hi-eff
A34: resid dishwashers | B34: electricity | C34: dishwasher | D34: 485 | E34: 485 | F34: 485 | G34: 485 | H34: 485 | I34: 485 | J34: 485 | K34: 485 | L34: 485 | M34: 485 | N34: 2017$/unit | P34: 0.15 | Q34: 12.6 | R34: 215 | S34: cycles/unit/yr | T34: =-PMT($P34,$Q34,D34)*$AE$1/$R34 -> 0.11300991 | U34: =-PMT($P34,$Q34,E34)*$AE$1/$R34 -> 0.11300991 | V34: =-PMT($P34,$Q34,F34)*$AE$1/$R34 -> 0.11300991 | W34: =-PMT($P34,$Q34,G34)*$AE$1/$R34 -> 0.11300991 | X34: =-PMT($P34,$Q34,H34)*$AE$1/$R34 -> 0.11300991 | Y34: =-PMT($P34,$Q34,I34)*$AE$1/$R34 -> 0.11300991 | Z34: =-PMT($P34,$Q34,J34)*$AE$1/$R34 -> 0.11300991 | AA34: =-PMT($P34,$Q34,K34)*$AE$1/$R34 -> 0.11300991 | ... AC34: =-PMT($P34,$Q34,M34)*$AE$1/$R34 -> 0.11300991 | AD34: 1975$/cycle | AE34: =A34&B34&C34 -> resid dishwasherselectricitydishwasher
A35: resid dishwashers | B35: electricity | C35: dishwasher hi-eff | D35: 485 | E35: 485 | F35: 485 | G35: 485 | H35: 485 | I35: 485 | J35: 485 | K35: 485 | L35: 485 | M35: 485 | N35: 2017$/unit | P35: 0.15 | Q35: 12.6 | R35: 215 | S35: cycles/unit/yr | T35: =-PMT($P35,$Q35,D35)*$AE$1/$R35 -> 0.11300991 | U35: =-PMT($P35,$Q35,E35)*$AE$1/$R35 -> 0.11300991 | V35: =-PMT($P35,$Q35,F35)*$AE$1/$R35 -> 0.11300991 | W35: =-PMT($P35,$Q35,G35)*$AE$1/$R35 -> 0.11300991 | X35: =-PMT($P35,$Q35,H35)*$AE$1/$R35 -> 0.11300991 | Y35: =-PMT($P35,$Q35,I35)*$AE$1/$R35 -> 0.11300991 | Z35: =-PMT($P35,$Q35,J35)*$AE$1/$R35 -> 0.11300991 | AA35: =-PMT($P35,$Q35,K35)*$AE$1/$R35 -> 0.11300991 | ... AC35: =-PMT($P35,$Q35,M35)*$AE$1/$R35 -> 0.11300991 | AD35: 1975$/cycle | AE35: =A35&B35&C35 -> resid dishwasherselectricitydishwasher hi-eff
A36: resid televisions | B36: electricity | C36: electricity
A37: resid computers | B37: electricity | C37: electricity
A38: resid furnace fans | B38: electricity | C38: electricity
A39: resid other | B39: gas | C39: gas
A40: resid other | B40: electricity | C40: electricity
A41: resid other | B41: refined liquids | C41: refined liquids

Sheet comm_cost
V1: To GCAM | AE1: 0.2765789
A2: supplysector | B2: subsector | C2: technology | D2: 2010 | E2: 2015 | F2: 2020 | G2: 2025 | H2: 2030 | I2: 2035 | J2: 2040 | K2: 2045 | L2: 2050 | M2: 2100 | N2: Unit | O2: O&M cost | Q2: Discount rate | R2: Lifetime | S2: Capacity factor | T2: Output | U2: Output unit | V2: 2010 | W2: 2015 | X2: 2020 | Y2: 2025 | Z2: 2030 | AA2: 2035 | AB2: 2040 | AC2: 2045 | AD2: 2050 | AE2: 2100
A3: comm heating | B3: gas | C3: gas furnace | D3: 7.2694035 | E3: 7.2694035 | F3: 7.2694035 | G3: 7.333982 | H3: 7.371316 | I3: 7.4001037 | J3: 7.4186433 | K3: 7.4326355 | L3: 7.4446401 | M3: 7.4446401 | N3: $/1000 btu/hr | O3: =[1]ktek_AT15_slim!$G$123 -> 1.0319252 | Q3: 0.25 | R3: =[1]ktek_AT15_slim!$J$123 -> 15 | S3: 0.11 | T3: =1000*1.0551*8760*S3/1000000 -> 1.0166944 | U3: GJ/yr | V3: =(-PMT($Q3,$R3,D3)+$O3)*$AE$1/$T3 -> 0.79313873 | W3: =(-PMT($Q3,$R3,E3)+$O3)*$AE$1/$T3 -> 0.79313873 | X3: =(-PMT($Q3,$R3,F3)+$O3)*$AE$1/$T3 -> 0.79313873 | Y3: =(-PMT($Q3,$R3,G3)+$O3)*$AE$1/$T3 -> 0.79769083 | Z3: =(-PMT($Q3,$R3,H3)+$O3)*$AE$1/$T3 -> 0.80032249 | AA3: =(-PMT($Q3,$R3,I3)+$O3)*$AE$1/$T3 -> 0.80235172 | AB3: =(-PMT($Q3,$R3,J3)+$O3)*$AE$1/$T3 -> 0.80365857 | AC3: =(-PMT($Q3,$R3,K3)+$O3)*$AE$1/$T3 -> 0.80464487 | ... AE3: =(-PMT($Q3,$R3,M3)+$O3)*$AE$1/$T3 -> 0.80549107 | AF3: =A3&B3&C3 -> comm heatinggasgas furnace
A4: comm heating | B4: gas | C4: gas furnace hi-eff | D4: 7.2694035 | E4: 7.2694035 | F4: 7.2694035 | G4: 7.333982 | H4: 7.371316 | I4: 7.4001037 | J4: 7.4186433 | K4: 7.4326355 | L4: 7.4446401 | M4: 7.4446401 | N4: $/1000 btu/hr | O4: =[1]ktek_AT15_slim!$G$124 -> 2.6563839 | Q4: 0.25 | R4: =[1]ktek_AT15_slim!$J$124 -> 15 | S4: 0.11 | T4: =1000*1.0551*8760*S4/1000000 -> 1.0166944 | U4: GJ/yr | V4: =(-PMT($Q4,$R4,D4)+$O4)*$AE$1/$T4 -> 1.2350523 | W4: =(-PMT($Q4,$R4,E4)+$O4)*$AE$1/$T4 -> 1.2350523 | X4: =(-PMT($Q4,$R4,F4)+$O4)*$AE$1/$T4 -> 1.2350523 | Y4: =(-PMT($Q4,$R4,G4)+$O4)*$AE$1/$T4 -> 1.2396044 | Z4: =(-PMT($Q4,$R4,H4)+$O4)*$AE$1/$T4 -> 1.242236 | AA4: =(-PMT($Q4,$R4,I4)+$O4)*$AE$1/$T4 -> 1.2442653 | AB4: =(-PMT($Q4,$R4,J4)+$O4)*$AE$1/$T4 -> 1.2455721 | AC4: =(-PMT($Q4,$R4,K4)+$O4)*$AE$1/$T4 -> 1.2465584 | ... AE4: =(-PMT($Q4,$R4,M4)+$O4)*$AE$1/$T4 -> 1.2474046 | AF4: =A4&B4&C4 -> comm heatinggasgas furnace hi-eff
A5: comm heating | B5: electricity | C5: electric furnace | D5: 37.35 | E5: 37.35 | F5: 37.35 | G5: 37.35 | H5: 37.35 | I5: 37.35 | J5: 37.35 | K5: 37.35 | L5: 37.35 | M5: 37.35 | N5: $/1000 btu/hr | O5: =[1]ktek_AT15_slim!$G$121 -> 0.01 | Q5: 0.25 | R5: =[1]ktek_AT15_slim!$J$121 -> 18 | S5: 0.11 | T5: =1000*1.0551*8760*S5/1000000 -> 1.0166944 | U5: GJ/yr | V5: =(-PMT($Q5,$R5,D5)+$O5)*$AE$1/$T5 -> 2.5894684 | W5: =(-PMT($Q5,$R5,E5)+$O5)*$AE$1/$T5 -> 2.5894684 | X5: =(-PMT($Q5,$R5,F5)+$O5)*$AE$1/$T5 -> 2.5894684 | Y5: =(-PMT($Q5,$R5,G5)+$O5)*$AE$1/$T5 -> 2.5894684 | Z5: =(-PMT($Q5,$R5,H5)+$O5)*$AE$1/$T5 -> 2.5894684 | AA5: =(-PMT($Q5,$R5,I5)+$O5)*$AE$1/$T5 -> 2.5894684 | AB5: =(-PMT($Q5,$R5,J5)+$O5)*$AE$1/$T5 -> 2.5894684 | AC5: =(-PMT($Q5,$R5,K5)+$O5)*$AE$1/$T5 -> 2.5894684 | ... AE5: =(-PMT($Q5,$R5,M5)+$O5)*$AE$1/$T5 -> 2.5894684 | AF5: =A5&B5&C5 -> comm heatingelectricityelectric furnace
A6: comm heating | B6: electricity | C6: electric heat pump | D6: 141.2 | E6: 141.2 | F6: 141.2 | G6: 141.2 | H6: 141.2 | I6: 141.2 | J6: 141.2 | K6: 141.2 | L6: 141.2 | M6: 141.2 | N6: $/1000 btu/hr | O6: =[1]ktek_AT15_slim!$G$97 -> 1.4722222 | Q6: 0.25 | R6: =[1]ktek_AT15_slim!$J$97 -> 15 | S6: 0.11 | T6: =1000*1.0551*8760*S6/1000000 -> 1.0166944 | U6: GJ/yr | V6: =(-PMT($Q6,$R6,D6)+$O6)*$AE$1/$T6 -> 10.353614 | W6: =(-PMT($Q6,$R6,E6)+$O6)*$AE$1/$T6 -> 10.353614 | X6: =(-PMT($Q6,$R6,F6)+$O6)*$AE$1/$T6 -> 10.353614 | Y6: =(-PMT($Q6,$R6,G6)+$O6)*$AE$1/$T6 -> 10.353614 | Z6: =(-PMT($Q6,$R6,H6)+$O6)*$AE$1/$T6 -> 10.353614 | AA6: =(-PMT($Q6,$R6,I6)+$O6)*$AE$1/$T6 -> 10.353614 | AB6: =(-PMT($Q6,$R6,J6)+$O6)*$AE$1/$T6 -> 10.353614 | AC6: =(-PMT($Q6,$R6,K6)+$O6)*$AE$1/$T6 -> 10.353614 | ... AE6: =(-PMT($Q6,$R6,M6)+$O6)*$AE$1/$T6 -> 10.353614 | AF6: =A6&B6&C6 -> comm heatingelectricityelectric heat pump
A7: comm heating | B7: refined liquids | C7: fuel furnace | D7: 20.493856 | E7: 20.493856 | F7: 20.493856 | G7: 20.509441 | H7: 20.531745 | I7: 20.565326 | J7: 20.619064 | K7: 20.716833 | L7: 20.793865 | M7: 20.793865 | N7: $/1000 btu/hr | O7: =[1]ktek_AT15_slim!$G$140 -> 0.16975309 | Q7: 0.25 | R7: =[1]ktek_AT15_slim!$J$140 -> 30 | S7: 0.11 | T7: =1000*1.0551*8760*S7/1000000 -> 1.0166944 | U7: GJ/yr | V7: =(-PMT($Q7,$R7,D7)+$O7)*$AE$1/$T7 -> 1.4416806 | W7: =(-PMT($Q7,$R7,E7)+$O7)*$AE$1/$T7 -> 1.4416806 | X7: =(-PMT($Q7,$R7,F7)+$O7)*$AE$1/$T7 -> 1.4416806 | Y7: =(-PMT($Q7,$R7,G7)+$O7)*$AE$1/$T7 -> 1.4427418 | Z7: =(-PMT($Q7,$R7,H7)+$O7)*$AE$1/$T7 -> 1.4442606 | AA7: =(-PMT($Q7,$R7,I7)+$O7)*$AE$1/$T7 -> 1.4465473 | AB7: =(-PMT($Q7,$R7,J7)+$O7)*$AE$1/$T7 -> 1.4502065 | AC7: =(-PMT($Q7,$R7,K7)+$O7)*$AE$1/$T7 -> 1.4568639 | ... AE7: =(-PMT($Q7,$R7,M7)+$O7)*$AE$1/$T7 -> 1.4621093 | AF7: =A7&B7&C7 -> comm heatingrefined liquidsfuel furnace
